Workbook

Sheet JUL 25
A1: SITA DEVI PANDEY HOUSING PROJECT
A2: 11/1B/1 GANPAT RAI KHEMKA LANE LILUAH HOWRAH(W. B.) 711204
A3: FOR THE MONTH OF - JUL 2025 | U3: 44
A4: SNO | B4: NAME | C4: ROOM | D4: DATE OF | E4: ELECTRIC | F4: MTLY | G4: ELECTRIC | K4: MISC | L4: B/F & | M4: TOTAL | N4: AMT | O4: B/F OR | P4: PAYMENT | Q4: REMARKS
C5: NO | D5: ALLOTMENT | E5: SECURITY | F5: RENT | G5: NEW | H5: PRE | I5: TOTAL | J5: COST | K5: RENT | L5: ADV | M5: AMT DUE | N5: PAID | O5: ADV | P5: DATE
A6: 1 | B6: AKHILESH RAI | C6: G/1 | D6: 38754 | E6: 0 | F6: 1900 | G6: 1644 | H6: ='JUN 25'!G6 -> 1590 | I6: =G6-H6 -> 54 | J6: =I6*12 -> 648 | K6: 300 | L6: ='JUN 25'!O6 -> 5336 | M6: =F6+J6+K6+L6 -> 8184 | N6: 0 | O6: =M6-N6 -> 8184 | Q6: ALLOTED WEF MAY 2025. ADV 5000. RENT 1900
A7: 2 | B7: LAXMI SHARMA | C7: G/2 | D7: 37653 | E7: 0 | F7: 1900 | G7: 724 | H7: ='JUN 25'!G7 -> 699 | I7: =G7-H7 -> 25 | J7: =I7*12 -> 300 | K7: 300 | L7: ='JUN 25'!O7 -> 1960 | M7: =F7+J7+K7+L7 -> 4460 | N7: 0 | O7: =M7-N7 -> 4460 | Q7: AGAIN ALLT WEF JUN 25. ADV NIL RENT 1900
A8: 3 | B8: PANKAJ PATEL | C8: G/3 | D8: 37895 | E8: 0 | F8: 2200 | G8: 4518 | H8: ='JUN 25'!G8 -> 4503 | I8: =G8-H8 -> 15 | J8: =I8*12 -> 180 | K8: 300 | L8: ='JUN 25'!O8 -> 22710 | M8: =F8+J8+K8+L8 -> 25390 | N8: 0 | O8: =M8-N8 -> 25390 | Q8: ALLOTED WEF JUL 21. ADV 5K, RENT 2200 FM JUL 24.
A9: 4 | B9: BADRI MANDAL | C9: G/4 | D9: 38292 | E9: 500 | F9: 2000 | G9: 4697 | H9: ='JUN 25'!G9 -> 4667 | I9: =G9-H9 -> 30 | J9: =I9*12 -> 360 | K9: 300 | L9: ='JUN 25'!O9 -> 14018 | M9: =F9+J9+K9+L9 -> 16678 | N9: 0 | O9: =M9-N9 -> 16678 | Q9: ALLOTED WEF 01 DEC 2022. RENT 2000. ADV 5000
A10: 5 | B10: VACANT | C10: G/5 | F10: 0 | G10: 4304 | H10: ='JUN 25'!G10 -> 4299 | I10: =G10-H10 -> 5 | J10: =I10*12 -> 60 | K10: 0 | L10: ='JUN 25'!O10 -> 24 | M10: =F10+J10+K10+L10 -> 84 | N10: 0 | O10: =M10-N10 -> 84 | Q10: VACANT FROM JUL 24
A11: 6 | B11: VIVEK MANDAL | C11: G/6 | D11: 37667 | E11: 500 | F11: 2000 | G11: 2301 | H11: ='JUN 25'!G11 -> 2262 | I11: =G11-H11 -> 39 | J11: =I11*12 -> 468 | K11: 300 | L11: ='JUN 25'!O11 -> 35876 | M11: =F11+J11+K11+L11 -> 38644 | N11: 0 | O11: =M11-N11 -> 38644 | Q11: ALLOTED WEF JUN 24. ADV 4000, RENT 2000
A12: 7 | B12: RAM P SHRESTHA | C12: G/7 | D12: 37773 | E12: 500 | F12: 2200 | G12: 5090 | H12: ='JUN 25'!G12 -> 5067 | I12: =G12-H12 -> 23 | J12: =I12*12 -> 276 | K12: 300 | L12: ='JUN 25'!O12 -> 8220 | M12: =F12+J12+K12+L12 -> 10996 | N12: 0 | O12: =M12-N12 -> 10996 | Q12: ALLOTED WEF SEP 21. ADV 10000. RENT 2000
A13: 8 | B13: AJAY BAG | C13: G/8 | D13: 37469 | E13: 500 | F13: 1800 | G13: 3687 | H13: ='JUN 25'!G13 -> 3658 | I13: =G13-H13 -> 29 | J13: =I13*12 -> 348 | K13: 300 | L13: ='JUN 25'!O13 -> 18698 | M13: =F13+J13+K13+L13 -> 21146 | N13: 0 | O13: =M13-N13 -> 21146 | Q13: ALLOTED WEF MAR 22. ADV 10000. RENT 1800
A14: 9 | B14: NEW | C14: G/9 | D14: 37347 | E14: 500 | F14: 2000 | G14: 12867 | H14: ='JUN 25'!G14 -> 12861 | I14: =G14-H14 -> 6 | J14: =I14*12 -> 72 | K14: 300 | L14: ='JUN 25'!O14 -> 0 | M14: =F14+J14+K14+L14 -> 2372 | N14: 0 | O14: =M14-N14 -> 2372 | Q14: ALLOTED WEF JUL 25. ADV 5K. RENT 2000
A15: 10 | B15: PRAMOD MANDAL | C15: G/10 | D15: 37165 | E15: 500 | F15: 2000 | G15: 4173 | H15: ='JUN 25'!G15 -> 4117 | I15: =G15-H15 -> 56 | J15: =I15*12 -> 672 | K15: 300 | L15: ='JUN 25'!O15 -> 0 | M15: =F15+J15+K15+L15 -> 2972 | N15: 0 | O15: =M15-N15 -> 2972 | Q15: ALLOTED WEF SEP 22. ADV 10000 RENT 2000
A16: 11 | B16: VACANT | C16: 1/1 | D16: 38443 | E16: 0 | F16: 0 | G16: 882 | H16: ='JUN 25'!G16 -> 865 | I16: =G16-H16 -> 17 | J16: =I16*12 -> 204 | K16: 0 | L16: ='JUN 25'!O16 -> 0 | M16: =F16+J16+K16+L16 -> 204 | N16: 0 | O16: =M16-N16 -> 204 | Q16: VACANT FROM DEC 24
A17: 12 | B17: VACANT | C17: 1/2 | D17: 38292 | F17: 0 | G17: 6912 | H17: ='JUN 25'!G17 -> 6912 | I17: =G17-H17 -> 0 | J17: =I17*12 -> 0 | K17: 0 | L17: ='JUN 25'!O17 -> 0 | M17: =F17+J17+K17+L17 -> 0 | N17: 0 | O17: =M17-N17 -> 0 | Q17: VACANT FROM FEB 25.
A18: 13 | B18: VACAMT | C18: 1/3 | D18: 38292 | E18: 500 | F18: 0 | G18: 5661 | H18: 5661 | I18: =G18-H18 -> 0 | J18: =I18*12 -> 0 | K18: 0 | L18: ='JUN 25'!O18 -> 0 | M18: =F18+J18+K18+L18 -> 0 | N18: 0 | O18: =M18-N18 -> 0 | Q18: VACANT FROM AUG 24
A19: 14 | B19: VACANT | C19: 1/4 | D19: 38292 | E19: 500 | F19: 0 | G19: 4194 | H19: ='JUN 25'!G19 -> 4194 | I19: =G19-H19 -> 0 | J19: =I19*12 -> 0 | K19: 0 | L19: ='JUN 25'!O19 -> 0 | M19: =F19+J19+K19+L19 -> 0 | N19: 0 | O19: =M19-N19 -> 0 | Q19: VACANT FROM MAY 2025
A20: 15 | B20: VACANT | C20: 1/5 | D20: 37469 | E20: 500 | F20: 0 | G20: 4250 | H20: 4250 | I20: =G20-H20 -> 0 | J20: =I20*12 -> 0 | K20: 0 | L20: ='JUN 25'!O20 -> 0 | M20: =F20+J20+K20+L20 -> 0 | N20: 0 | O20: =M20-N20 -> 0 | Q20: VACANT WEF NOV 2023
A21: 16 | B21: SHAILENDRA PANDEY | C21: 1/6 | D21: 37681 | E21: 500 | F21: 3000 | G21: 3718 | H21: ='JUN 25'!G21 -> 3636 | I21: =G21-H21 -> 82 | J21: =I21*12 -> 984 | K21: 400 | L21: ='JUN 25'!O21 -> 42646 | M21: =F21+J21+K21+L21 -> 47030 | N21: 0 | O21: =M21-N21 -> 47030 | Q21: RENT INCREASED WEF MAR 24 FROM 2300. ADV 10000
A22: 17 | B22: BIRENDAR YADAV | C22: 2/1 | D22: 38292 | E22: 500 | F22: 2800 | G22: 908 | H22: ='JUN 25'!G22 -> 879 | I22: =G22-H22 -> 29 | J22: =I22*12 -> 348 | K22: 400 | L22: ='JUN 25'!O22 -> 49824 | M22: =F22+J22+K22+L22 -> 53372 | N22: 0 | O22: =M22-N22 -> 53372 | Q22: RENT INCREASED WEF DEC 22 FROM 2200. ADV NIL
A23: 18 | B23: HARI SHANKER SHUKLA | C23: 2/2 | D23: 38292 | E23: 500 | F23: 3100 | G23: 1101 | H23: ='JUN 25'!G23 -> 1078 | I23: =G23-H23 -> 23 | J23: =I23*12 -> 276 | K23: 400 | L23: ='JUN 25'!O23 -> 24394 | M23: =F23+J23+K23+L23 -> 28170 | N23: 0 | O23: =M23-N23 -> 28170 | Q23: RENT INCRESED WEF JUL 24 FROM 2700. ADV 10000
A24: 19 | B24: SHIV SHANKER PANDEY | C24: 2/3 | D24: 37681 | E24: 500 | F24: 2800 | G24: 5582 | H24: ='JUN 25'!G24 -> 5561 | I24: =G24-H24 -> 21 | J24: =I24*12 -> 252 | K24: 400 | L24: ='JUN 25'!O24 -> 0 | M24: =F24+J24+K24+L24 -> 3452 | N24: 0 | O24: =M24-N24 -> 3452 | Q24: REALLOTED WEF DEC 22. RENT 2800. ADV NIL
A25: 20 | B25: PRAKASH PANDEY | C25: 2/4 | D25: 37681 | E25: 0 | F25: 2800 | G25: 1350 | H25: ='JUN 25'!G25 -> 1310 | I25: =G25-H25 -> 40 | J25: =I25*12 -> 480 | K25: 400 | L25: ='JUN 25'!O25 -> 3916 | M25: =F25+J25+K25+L25 -> 7596 | N25: 0 | O25: =M25-N25 -> 7596 | Q25: ALLOTED FROM DEC 23. ADV NIL. RENT 2800
A26: 21 | B26: VACANT | C26: 2/5 | D26: 37681 | E26: 500 | F26: 0 | G26: 3439 | H26: ='JUN 25'!G26 -> 3439 | I26: =G26-H26 -> 0 | J26: =I26*12 -> 0 | K26: 0 | L26: 0 | M26: =F26+J26+K26+L26 -> 0 | N26: 0 | O26: =M26-N26 -> 0 | Q26: VACATED WEF JUN 25.
A27: 22 | B27: SUNITA SINGH | C27: 2/6 | D27: 37681 | E27: 0 | F27: 3100 | G27: 5202 | H27: ='JUN 25'!G27 -> 5171 | I27: =G27-H27 -> 31 | J27: =I27*12 -> 372 | K27: 400 | L27: ='JUN 25'!O27 -> -4 | M27: =F27+J27+K27+L27 -> 3868 | N27: 0 | O27: =M27-N27 -> 3868 | Q27: ALLOTED WEF MAY 2025. ADV 15000, RENT 3100
C28: TOTAL | E28: =SUM(E6:E27) -> 7000 | F28: =SUM(F6:F27) -> 35600 | I28: =SUM(I6:I27) -> 525 | J28: =SUM(J6:J27) -> 6300 | K28: =SUM(K6:K27) -> 5100 | L28: =SUM(L6:L27) -> 227618 | M28: =SUM(M6:M27) -> 274618 | N28: =SUM(N6:N27) -> 0 | O28: =SUM(O6:O27) -> 274618

Sheet JUN 25
A1: SITA DEVI PANDEY HOUSING PROJECT
A2: 11/1B/1 GANPAT RAI KHEMKA LANE LILUAH HOWRAH(W. B.) 711204
A3: FOR THE MONTH OF - JUN 2025 | U3: 44
A4: SNO | B4: NAME | C4: ROOM | D4: DATE OF | E4: ELECTRIC | F4: MTLY | G4: ELECTRIC | K4: MISC | L4: B/F & | M4: TOTAL | N4: AMT | O4: B/F OR | P4: PAYMENT | Q4: REMARKS
C5: NO | D5: ALLOTMENT | E5: SECURITY | F5: RENT | G5: NEW | H5: PRE | I5: TOTAL | J5: COST | K5: RENT | L5: ADV | M5: AMT DUE | N5: PAID | O5: ADV | P5: DATE
A6: 1 | B6: AKHILESH RAI | C6: G/1 | D6: 38754 | E6: 0 | F6: 1900 | G6: 1590 | H6: ='MAY 25'!G6 -> 1544 | I6: =G6-H6 -> 46 | J6: =I6*12 -> 552 | K6: 300 | L6: ='MAY 25'!O6 -> 2584 | M6: =F6+J6+K6+L6 -> 5336 | N6: 0 | O6: =M6-N6 -> 5336 | Q6: ALLOTED WEF MAY 2025. ADV 5000. RENT 1900
A7: 2 | B7: LAXMI SHARMA | C7: G/2 | D7: 37653 | E7: 0 | F7: 1900 | G7: 699 | H7: ='MAY 25'!G7 -> 689 | I7: =G7-H7 -> 10 | J7: =I7*12 -> 120 | K7: 300 | L7: ='MAY 25'!O7 -> -360 | M7: =F7+J7+K7+L7 -> 1960 | N7: 0 | O7: =M7-N7 -> 1960 | Q7: AGAIN ALLT WEF JUN 25. ADV NIL RENT 1900
A8: 3 | B8: PANKAJ PATEL | C8: G/3 | D8: 37895 | E8: 0 | F8: 2200 | G8: 4503 | H8: ='MAY 25'!G8 -> 4481 | I8: =G8-H8 -> 22 | J8: =I8*12 -> 264 | K8: 300 | L8: ='MAY 25'!O8 -> 19946 | M8: =F8+J8+K8+L8 -> 22710 | N8: 0 | O8: =M8-N8 -> 22710 | Q8: ALLOTED WEF JUL 21. ADV 5K, RENT 2200 FM JUL 24.
A9: 4 | B9: BADRI MANDAL | C9: G/4 | D9: 38292 | E9: 500 | F9: 2000 | G9: 4667 | H9: 4622 | I9: =G9-H9 -> 45 | J9: =I9*12 -> 540 | K9: 300 | L9: ='MAY 25'!O9 -> 11178 | M9: =F9+J9+K9+L9 -> 14018 | N9: 0 | O9: =M9-N9 -> 14018 | Q9: ALLOTED WEF 01 DEC 2022. RENT 2000. ADV 5000
A10: 5 | B10: VACANT | C10: G/5 | F10: 0 | G10: 4299 | H10: ='MAY 25'!G10 -> 4297 | I10: =G10-H10 -> 2 | J10: =I10*12 -> 24 | K10: 0 | L10: ='MAY 25'!O10 -> 0 | M10: =F10+J10+K10+L10 -> 24 | N10: 0 | O10: =M10-N10 -> 24 | Q10: VACANT FROM JUL 24
A11: 6 | B11: VIVEK MANDAL | C11: G/6 | D11: 37667 | E11: 500 | F11: 2000 | G11: 2262 | H11: ='MAY 25'!G11 -> 2224 | I11: =G11-H11 -> 38 | J11: =I11*12 -> 456 | K11: 300 | L11: ='MAY 25'!O11 -> 33120 | M11: =F11+J11+K11+L11 -> 35876 | N11: 0 | O11: =M11-N11 -> 35876 | Q11: ALLOTED WEF JUN 24. ADV 4000, RENT 2000
A12: 7 | B12: RAM P SHRESTHA | C12: G/7 | D12: 37773 | E12: 500 | F12: 2200 | G12: 5067 | H12: ='MAY 25'!G12 -> 5046 | I12: =G12-H12 -> 21 | J12: =I12*12 -> 252 | K12: 300 | L12: ='MAY 25'!O12 -> 5468 | M12: =F12+J12+K12+L12 -> 8220 | N12: 0 | O12: =M12-N12 -> 8220 | Q12: ALLOTED WEF SEP 21. ADV 10000. RENT 2000
A13: 8 | B13: AJAY BAG | C13: G/8 | D13: 37469 | E13: 500 | F13: 1800 | G13: 3658 | H13: ='MAY 25'!G13 -> 3620 | I13: =G13-H13 -> 38 | J13: =I13*12 -> 456 | K13: 300 | L13: ='MAY 25'!O13 -> 26142 | M13: =F13+J13+K13+L13 -> 28698 | N13: 10000 | O13: =M13-N13 -> 18698 | Q13: ALLOTED WEF MAR 22. ADV 10000. RENT 1800
A14: 9 | B14: VACANT | C14: G/9 | D14: 37347 | E14: 500 | F14: 0 | G14: 12861 | H14: ='MAY 25'!G14 -> 12861 | I14: =G14-H14 -> 0 | J14: =I14*12 -> 0 | K14: 0 | L14: ='MAY 25'!O14 -> 0 | M14: =F14+J14+K14+L14 -> 0 | N14: 0 | O14: =M14-N14 -> 0 | Q14: VACATED WEF OCT 24.
A15: 10 | B15: PRAMOD MANDAL | C15: G/10 | D15: 37165 | E15: 500 | F15: 2000 | G15: 4117 | H15: ='MAY 25'!G15 -> 4050 | I15: =G15-H15 -> 67 | J15: =I15*12 -> 804 | K15: 300 | L15: ='MAY 25'!O15 -> 0 | M15: =F15+J15+K15+L15 -> 3104 | N15: 3104 | O15: =M15-N15 -> 0 | Q15: ALLOTED WEF SEP 22. ADV 10000 RENT 2000
A16: 11 | B16: VACANT | C16: 1/1 | D16: 38443 | E16: 0 | F16: 0 | G16: 865 | H16: ='MAY 25'!G16 -> 865 | I16: =G16-H16 -> 0 | J16: =I16*12 -> 0 | K16: 0 | L16: ='MAY 25'!O16 -> 0 | M16: =F16+J16+K16+L16 -> 0 | N16: 0 | O16: =M16-N16 -> 0 | Q16: VACANT FROM DEC 24
A17: 12 | B17: VACANT | C17: 1/2 | D17: 38292 | F17: 0 | G17: 6912 | H17: ='MAY 25'!G17 -> 6912 | I17: =G17-H17 -> 0 | J17: =I17*12 -> 0 | K17: 0 | L17: ='MAY 25'!O17 -> 0 | M17: =F17+J17+K17+L17 -> 0 | N17: 0 | O17: =M17-N17 -> 0 | Q17: VACANT FROM FEB 25.
A18: 13 | B18: VACAMT | C18: 1/3 | D18: 38292 | E18: 500 | F18: 0 | G18: 5655 | H18: ='MAY 25'!G18 -> 5655 | I18: =G18-H18 -> 0 | J18: =I18*12 -> 0 | K18: 0 | L18: ='MAY 25'!O18 -> 0 | M18: =F18+J18+K18+L18 -> 0 | N18: 0 | O18: =M18-N18 -> 0 | Q18: VACANT FROM AUG 24
A19: 14 | B19: VACANT | C19: 1/4 | D19: 38292 | E19: 500 | F19: 0 | G19: 4194 | H19: ='MAY 25'!G19 -> 4194 | I19: =G19-H19 -> 0 | J19: =I19*12 -> 0 | K19: 0 | L19: 0 | M19: =F19+J19+K19+L19 -> 0 | N19: 0 | O19: =M19-N19 -> 0 | Q19: VACATED FROM MAY 2025. REFUND 3228
A20: 15 | B20: VACANT | C20: 1/5 | D20: 37469 | E20: 500 | F20: 0 | G20: 4247 | H20: 4247 | I20: =G20-H20 -> 0 | J20: =I20*12 -> 0 | K20: 0 | L20: ='MAY 25'!O20 -> 0 | M20: =F20+J20+K20+L20 -> 0 | N20: 0 | O20: =M20-N20 -> 0 | Q20: VACANT WEF NOV 2023
A21: 16 | B21: SHAILENDRA PANDEY | C21: 1/6 | D21: 37681 | E21: 500 | F21: 3000 | G21: 3636 | H21: ='MAY 25'!G21 -> 3609 | I21: =G21-H21 -> 27 | J21: =I21*12 -> 324 | K21: 5400 | L21: ='MAY 25'!O21 -> 33922 | M21: =F21+J21+K21+L21 -> 42646 | N21: 0 | O21: =M21-N21 -> 42646 | Q21: RENT INCREASED WEF MAR 24 FROM 2300. ADV 10000
A22: 17 | B22: BIRENDAR YADAV | C22: 2/1 | D22: 38292 | E22: 500 | F22: 2800 | G22: 879 | H22: ='MAY 25'!G22 -> 848 | I22: =G22-H22 -> 31 | J22: =I22*12 -> 372 | K22: 3400 | L22: ='MAY 25'!O22 -> 43252 | M22: =F22+J22+K22+L22 -> 49824 | N22: 0 | O22: =M22-N22 -> 49824 | Q22: RENT INCREASED WEF DEC 22 FROM 2200. ADV NIL
A23: 18 | B23: HARI SHANKER SHUKLA | C23: 2/2 | D23: 38292 | E23: 500 | F23: 3100 | G23: 1078 | H23: ='MAY 25'!G23 -> 1070 | I23: =G23-H23 -> 8 | J23: =I23*12 -> 96 | K23: 1400 | L23: ='MAY 25'!O23 -> 19798 | M23: =F23+J23+K23+L23 -> 24394 | N23: 0 | O23: =M23-N23 -> 24394 | Q23: RENT INCRESED WEF JUL 24 FROM 2700. ADV 10000
A24: 19 | B24: SHIV SHANKER PANDEY | C24: 2/3 | D24: 37681 | E24: 500 | F24: 2800 | G24: 5561 | H24: ='MAY 25'!G24 -> 5544 | I24: =G24-H24 -> 17 | J24: =I24*12 -> 204 | K24: 400 | L24: ='MAY 25'!O24 -> 10 | M24: =F24+J24+K24+L24 -> 3414 | N24: 3414 | O24: =M24-N24 -> 0 | Q24: REALLOTED WEF DEC 22. RENT 2800. ADV NIL
A25: 20 | B25: PRAKASH PANDEY | C25: 2/4 | D25: 37681 | E25: 0 | F25: 2800 | G25: 1310 | H25: ='MAY 25'!G25 -> 1268 | I25: =G25-H25 -> 42 | J25: =I25*12 -> 504 | K25: 400 | L25: ='MAY 25'!O25 -> 4212 | M25: =F25+J25+K25+L25 -> 7916 | N25: 4000 | O25: =M25-N25 -> 3916 | Q25: ALLOTED FROM DEC 23. ADV NIL. RENT 2800
A26: 21 | B26: PAPPU | C26: 2/5 | D26: 37681 | E26: 500 | F26: 3000 | G26: 3439 | H26: ='MAY 25'!G26 -> 3412 | I26: =G26-H26 -> 27 | J26: =I26*12 -> 324 | K26: 400 | L26: ='MAY 25'!O26 -> 4896 | M26: =F26+J26+K26+L26 -> 8620 | N26: 10000 | O26: =M26-N26 -> -1380 | Q26: VACATED JUN 25. RETURNED 1380
A27: 22 | B27: SUNITA SINGH | C27: 2/6 | D27: 37681 | E27: 0 | F27: 3100 | G27: 5171 | H27: ='MAY 25'!G27 -> 5153 | I27: =G27-H27 -> 18 | J27: =I27*12 -> 216 | K27: 400 | L27: ='MAY 25'!O27 -> 0 | M27: =F27+J27+K27+L27 -> 3716 | N27: 3720 | O27: =M27-N27 -> -4 | Q27: ALLOTED WEF MAY 2025. ADV 15000, RENT 3100
C28: TOTAL | E28: =SUM(E6:E27) -> 7000 | F28: =SUM(F6:F27) -> 36600 | I28: =SUM(I6:I27) -> 459 | J28: =SUM(J6:J27) -> 5508 | K28: =SUM(K6:K27) -> 14200 | L28: =SUM(L6:L27) -> 204168 | M28: =SUM(M6:M27) -> 260476 | N28: =SUM(N6:N27) -> 34238 | O28: =SUM(O6:O27) -> 226238

Sheet MAY 25
A1: SITA DEVI PANDEY HOUSING PROJECT
A2: 11/1B/1 GANPAT RAI KHEMKA LANE LILUAH HOWRAH(W. B.) 711204
A3: FOR THE MONTH OF - MAY 2025 | U3: 44
A4: SNO | B4: NAME | C4: ROOM | D4: DATE OF | E4: ELECTRIC | F4: MTLY | G4: ELECTRIC | K4: MISC | L4: B/F & | M4: TOTAL | N4: AMT | O4: B/F OR | P4: PAYMENT | Q4: REMARKS
C5: NO | D5: ALLOTMENT | E5: SECURITY | F5: RENT | G5: NEW | H5: PRE | I5: TOTAL | J5: COST | K5: RENT | L5: ADV | M5: AMT DUE | N5: PAID | O5: ADV | P5: DATE
A6: 1 | B6: AKHILESH RAI | C6: G/1 | D6: 38754 | E6: 0 | F6: 1900 | G6: 1544 | H6: ='APR 25'!G6 -> 1512 | I6: =G6-H6 -> 32 | J6: =I6*12 -> 384 | K6: 300 | L6: 0 | M6: =F6+J6+K6+L6 -> 2584 | N6: 0 | O6: =M6-N6 -> 2584 | Q6: ALLOTED WEF MAY 2025. ADV 5000. RENT 1900
A7: 2 | B7: LAXMI SHARMA | C7: G/2 | D7: 37653 | E7: 0 | F7: 1900 | G7: 689 | H7: ='APR 25'!G7 -> 681 | I7: =G7-H7 -> 8 | J7: =I7*12 -> 96 | K7: 300 | L7: ='APR 25'!O7 -> 2344 | M7: =F7+J7+K7+L7 -> 4640 | N7: 5000 | O7: =M7-N7 -> -360 | Q7: VACATED ON MAY 2025. REFUND 360
A8: 3 | B8: PANKAJ PATEL | C8: G/3 | D8: 37895 | E8: 0 | F8: 2200 | G8: 4481 | H8: ='APR 25'!G8 -> 4474 | I8: =G8-H8 -> 7 | J8: =I8*12 -> 84 | K8: 300 | L8: ='APR 25'!O8 -> 20362 | M8: =F8+J8+K8+L8 -> 22946 | N8: 3000 | O8: =M8-N8 -> 19946 | Q8: ALLOTED WEF JUL 21. ADV 5K, RENT 2200 FM JUL 24.
A9: 4 | B9: BADRI MANDAL | C9: G/4 | D9: 38292 | E9: 500 | F9: 2000 | G9: 4671 | H9: ='APR 25'!G9 -> 4581 | I9: =G9-H9 -> 90 | J9: =I9*12 -> 1080 | K9: 300 | L9: ='APR 25'!O9 -> 7798 | M9: =F9+J9+K9+L9 -> 11178 | N9: 0 | O9: =M9-N9 -> 11178 | Q9: ALLOTED WEF 01 DEC 2022. RENT 2000. ADV 5000
A10: 5 | B10: VACANT | C10: G/5 | F10: 0 | G10: 4297 | H10: ='APR 25'!G10 -> 4297 | I10: =G10-H10 -> 0 | J10: =I10*12 -> 0 | K10: 0 | L10: ='APR 25'!O10 -> 0 | M10: =F10+J10+K10+L10 -> 0 | N10: 0 | O10: =M10-N10 -> 0 | Q10: VACANT FROM JUL 24
A11: 6 | B11: VIVEK MANDAL | C11: G/6 | D11: 37667 | E11: 500 | F11: 2000 | G11: 2224 | H11: ='APR 25'!G11 -> 2152 | I11: =G11-H11 -> 72 | J11: =I11*12 -> 864 | K11: 300 | L11: ='APR 25'!O11 -> 29956 | M11: =F11+J11+K11+L11 -> 33120 | N11: 0 | O11: =M11-N11 -> 33120 | Q11: ALLOTED WEF JUN 24. ADV 4000, RENT 2000
A12: 7 | B12: RAM P SHRESTHA | C12: G/7 | D12: 37773 | E12: 500 | F12: 2200 | G12: 5046 | H12: ='APR 25'!G12 -> 5007 | I12: =G12-H12 -> 39 | J12: =I12*12 -> 468 | K12: 300 | L12: ='APR 25'!O12 -> 8170 | M12: =F12+J12+K12+L12 -> 11138 | N12: 5670 | O12: =M12-N12 -> 5468 | Q12: ALLOTED WEF SEP 21. ADV 10000. RENT 2000
A13: 8 | B13: AJAY BAG | C13: G/8 | D13: 37469 | E13: 500 | F13: 1800 | G13: 3620 | H13: ='APR 25'!G13 -> 3501 | I13: =G13-H13 -> 119 | J13: =I13*12 -> 1428 | K13: 300 | L13: ='APR 25'!O13 -> 22614 | M13: =F13+J13+K13+L13 -> 26142 | N13: 0 | O13: =M13-N13 -> 26142 | Q13: ALLOTED WEF MAR 22. ADV 10000. RENT 1800
A14: 9 | B14: VACANT | C14: G/9 | D14: 37347 | E14: 500 | F14: 0 | G14: 12861 | H14: ='APR 25'!G14 -> 12861 | I14: =G14-H14 -> 0 | J14: =I14*12 -> 0 | K14: 0 | L14: ='APR 25'!O14 -> 0 | M14: =F14+J14+K14+L14 -> 0 | O14: =M14-N14 -> 0 | Q14: VACATED WEF OCT 24.
A15: 10 | B15: PRAMOD MANDAL | C15: G/10 | D15: 37165 | E15: 500 | F15: 2000 | G15: 4050 | H15: ='APR 25'!G15 -> 3938 | I15: =G15-H15 -> 112 | J15: =I15*12 -> 1344 | K15: 300 | L15: ='APR 25'!O15 -> -8 | M15: =F15+J15+K15+L15 -> 3636 | N15: 3636 | O15: =M15-N15 -> 0 | Q15: ALLOTED WEF SEP 22. ADV 10000 RENT 2000
A16: 11 | B16: VACANT | C16: 1/1 | D16: 38443 | E16: 0 | F16: 0 | G16: 865 | H16: ='APR 25'!G16 -> 865 | I16: =G16-H16 -> 0 | J16: =I16*12 -> 0 | K16: 0 | L16: ='APR 25'!O16 -> 0 | M16: =F16+J16+K16+L16 -> 0 | N16: 0 | O16: =M16-N16 -> 0 | Q16: VACANT FROM DEC 24
A17: 12 | B17: VACANT | C17: 1/2 | D17: 38292 | F17: 0 | G17: 6912 | H17: ='APR 25'!G17 -> 6912 | I17: =G17-H17 -> 0 | J17: =I17*12 -> 0 | K17: 0 | L17: ='APR 25'!O17 -> 0 | M17: =F17+J17+K17+L17 -> 0 | N17: 0 | O17: =M17-N17 -> 0 | Q17: VACANT FROM FEB 25.
A18: 13 | B18: VACAMT | C18: 1/3 | D18: 38292 | E18: 500 | F18: 0 | G18: 5655 | H18: ='APR 25'!G18 -> 5655 | I18: =G18-H18 -> 0 | J18: =I18*12 -> 0 | K18: 0 | L18: ='APR 25'!O18 -> 0 | M18: =F18+J18+K18+L18 -> 0 | N18: 0 | O18: =M18-N18 -> 0 | Q18: VACANT FROM AUG 24
A19: 14 | B19: ANIL SHARMA | C19: 1/4 | D19: 38292 | E19: 500 | F19: 3000 | G19: 4194 | H19: ='APR 25'!G19 -> 4151 | I19: =G19-H19 -> 43 | J19: =I19*12 -> 516 | K19: 400 | L19: ='APR 25'!O19 -> 7856 | M19: =F19+J19+K19+L19 -> 11772 | N19: 15000 | O19: =M19-N19 -> -3228 | Q19: VACATED FROM MAY 2025. REFUNDED 3228
A20: 15 | B20: VACANT | C20: 1/5 | D20: 37469 | E20: 500 | F20: 0 | G20: 4246 | H20: ='APR 25'!G20 -> 4246 | I20: =G20-H20 -> 0 | J20: =I20*12 -> 0 | K20: 0 | L20: ='APR 25'!O20 -> 0 | M20: =F20+J20+K20+L20 -> 0 | N20: 0 | O20: =M20-N20 -> 0 | Q20: VACANT WEF NOV 2023
A21: 16 | B21: SHAILENDRA PANDEY | C21: 1/6 | D21: 37681 | E21: 500 | F21: 3000 | G21: 3609 | H21: ='APR 25'!G21 -> 3551 | I21: =G21-H21 -> 58 | J21: =I21*12 -> 696 | K21: 400 | L21: ='APR 25'!O21 -> 29826 | M21: =F21+J21+K21+L21 -> 33922 | N21: 0 | O21: =M21-N21 -> 33922 | Q21: RENT INCREASED WEF MAR 24 FROM 2300. ADV 10000
A22: 17 | B22: BIRENDAR YADAV | C22: 2/1 | D22: 38292 | E22: 500 | F22: 2800 | G22: 848 | H22: ='APR 25'!G22 -> 816 | I22: =G22-H22 -> 32 | J22: =I22*12 -> 384 | K22: 400 | L22: ='APR 25'!O22 -> 39668 | M22: =F22+J22+K22+L22 -> 43252 | N22: 0 | O22: =M22-N22 -> 43252 | Q22: RENT INCREASED WEF DEC 22 FROM 2200. ADV NIL
A23: 18 | B23: HARI SHANKER SHUKLA | C23: 2/2 | D23: 38292 | E23: 500 | F23: 3100 | G23: 1070 | H23: ='APR 25'!G23 -> 1025 | I23: =G23-H23 -> 45 | J23: =I23*12 -> 540 | K23: 400 | L23: ='APR 25'!O23 -> 15758 | M23: =F23+J23+K23+L23 -> 19798 | N23: 0 | O23: =M23-N23 -> 19798 | Q23: RENT INCRESED WEF JUL 24 FROM 2700. ADV 10000
A24: 19 | B24: SHIV SHANKER PANDEY | C24: 2/3 | D24: 37681 | E24: 500 | F24: 2800 | G24: 5544 | H24: ='APR 25'!G24 -> 5505 | I24: =G24-H24 -> 39 | J24: =I24*12 -> 468 | K24: 400 | L24: ='APR 25'!O24 -> 0 | M24: =F24+J24+K24+L24 -> 3668 | N24: 3658 | O24: =M24-N24 -> 10 | Q24: REALLOTED WEF DEC 22. RENT 2800. ADV NIL
A25: 20 | B25: PRAKASH PANDEY | C25: 2/4 | D25: 37681 | E25: 0 | F25: 2800 | G25: 1268 | H25: ='APR 25'!G25 -> 1157 | I25: =G25-H25 -> 111 | J25: =I25*12 -> 1332 | K25: 400 | L25: ='APR 25'!O25 -> 6680 | M25: =F25+J25+K25+L25 -> 11212 | N25: 7000 | O25: =M25-N25 -> 4212 | Q25: ALLOTED FROM DEC 23. ADV NIL. RENT 2800
A26: 21 | B26: PAPPU | C26: 2/5 | D26: 37681 | E26: 500 | F26: 3000 | G26: 3412 | H26: ='APR 25'!G26 -> 3355 | I26: =G26-H26 -> 57 | J26: =I26*12 -> 684 | K26: 400 | L26: ='APR 25'!O26 -> 812 | M26: =F26+J26+K26+L26 -> 4896 | N26: 0 | O26: =M26-N26 -> 4896 | Q26: ALLOTED WEF DEC 24. ADV 10K, RENT 3100
A27: 22 | B27: SUNITA SINGH | C27: 2/6 | D27: 37681 | E27: 0 | F27: 3100 | G27: 5153 | H27: ='APR 25'!G27 -> 5104 | I27: =G27-H27 -> 49 | J27: =I27*12 -> 588 | K27: 400 | L27: ='APR 25'!O27 -> 0 | M27: =F27+J27+K27+L27 -> 4088 | N27: 4088 | O27: =M27-N27 -> 0 | Q27: ALLOTED WEF MAY 2025. ADV 15000, RENT 3100
C28: TOTAL | E28: =SUM(E6:E27) -> 7000 | F28: =SUM(F6:F27) -> 39600 | I28: =SUM(I6:I27) -> 913 | J28: =SUM(J6:J27) -> 10956 | K28: =SUM(K6:K27) -> 5600 | L28: =SUM(L6:L27) -> 191836 | M28: =SUM(M6:M27) -> 247992 | N28: =SUM(N6:N27) -> 47052 | O28: =SUM(O6:O27) -> 200940

Sheet APR 25
A1: SITA DEVI PANDEY HOUSING PROJECT
A2: 11/1B/1 GANPAT RAI KHEMKA LANE LILUAH HOWRAH(W. B.) 711204
A3: FOR THE MONTH OF - APR 2025 | U3: 44
A4: SNO | B4: NAME | C4: ROOM | D4: DATE OF | E4: ELECTRIC | F4: MTLY | G4: ELECTRIC | K4: MISC | L4: B/F & | M4: TOTAL | N4: AMT | O4: B/F OR | P4: PAYMENT | Q4: REMARKS
C5: NO | D5: ALLOTMENT | E5: SECURITY | F5: RENT | G5: NEW | H5: PRE | I5: TOTAL | J5: COST | K5: RENT | L5: ADV | M5: AMT DUE | N5: PAID | O5: ADV | P5: DATE
A6: 1 | B6: SUNNY PRAJAPATI | C6: G/1 | D6: 38754 | E6: 0 | F6: 2200 | G6: 1512 | H6: ='MAR 25'!G6 -> 1479 | I6: =G6-H6 -> 33 | J6: =I6*12 -> 396 | K6: 300 | L6: 20828 | M6: =F6+J6+K6+L6 -> 23724 | N6: 20724 | O6: =M6-N6 -> 3000 | Q6: VACATED WEF MAY 2025. 3000 DUE
A7: 2 | B7: LAXMI SHARMA | C7: G/2 | D7: 37653 | E7: 0 | F7: 1900 | G7: 681 | H7: ='MAR 25'!G7 -> 669 | I7: =G7-H7 -> 12 | J7: =I7*12 -> 144 | K7: 300 | L7: ='MAR 25'!O7 -> 0 | M7: =F7+J7+K7+L7 -> 2344 | N7: 0 | O7: =M7-N7 -> 2344 | Q7: ALLOTED WEF 07-03-2025. ADV 5K.RENT 1900
A8: 3 | B8: PANKAJ PATEL | C8: G/3 | D8: 37895 | E8: 0 | F8: 2200 | G8: 4474 | H8: ='MAR 25'!G8 -> 4470 | I8: =G8-H8 -> 4 | J8: =I8*12 -> 48 | K8: 300 | L8: ='MAR 25'!O8 -> 22814 | M8: =F8+J8+K8+L8 -> 25362 | N8: 5000 | O8: =M8-N8 -> 20362 | Q8: ALLOTED WEF JUL 21. ADV 5K, RENT 2200 FM JUL 24.
A9: 4 | B9: BADRI MANDAL | C9: G/4 | D9: 38292 | E9: 500 | F9: 2000 | G9: 4581 | H9: ='MAR 25'!G9 -> 4541 | I9: =G9-H9 -> 40 | J9: =I9*12 -> 480 | K9: 300 | L9: ='MAR 25'!O9 -> 15018 | M9: =F9+J9+K9+L9 -> 17798 | N9: 10000 | O9: =M9-N9 -> 7798 | Q9: ALLOTED WEF 01 DEC 2022. RENT 2000. ADV 5000
A10: 5 | B10: VACANT | C10: G/5 | F10: 0 | G10: 4297 | H10: ='MAR 25'!G10 -> 4297 | I10: =G10-H10 -> 0 | J10: =I10*12 -> 0 | K10: 0 | L10: ='MAR 25'!O10 -> 0 | M10: =F10+J10+K10+L10 -> 0 | N10: 0 | O10: =M10-N10 -> 0 | Q10: VACANT FROM JUL 24
A11: 6 | B11: VIVEK MANDAL | C11: G/6 | D11: 37667 | E11: 500 | F11: 2000 | G11: 2152 | H11: ='MAR 25'!G11 -> 2100 | I11: =G11-H11 -> 52 | J11: =I11*12 -> 624 | K11: 300 | L11: ='MAR 25'!O11 -> 27032 | M11: =F11+J11+K11+L11 -> 29956 | N11: 0 | O11: =M11-N11 -> 29956 | Q11: ALLOTED WEF JUN 24. ADV 4000, RENT 2000
A12: 7 | B12: RAM P SHRESTHA | C12: G/7 | D12: 37773 | E12: 500 | F12: 2200 | G12: 5007 | H12: ='MAR 25'!G12 -> 4974 | I12: =G12-H12 -> 33 | J12: =I12*12 -> 396 | K12: 300 | L12: ='MAR 25'!O12 -> 7824 | M12: =F12+J12+K12+L12 -> 10720 | N12: 2550 | O12: =M12-N12 -> 8170 | Q12: ALLOTED WEF SEP 21. ADV 10000. RENT 2000
A13: 8 | B13: AJAY BAG | C13: G/8 | D13: 37469 | E13: 500 | F13: 1800 | G13: 3501 | H13: ='MAR 25'!G13 -> 3462 | I13: =G13-H13 -> 39 | J13: =I13*12 -> 468 | K13: 300 | L13: ='MAR 25'!O13 -> 20046 | M13: =F13+J13+K13+L13 -> 22614 | N13: 0 | O13: =M13-N13 -> 22614 | Q13: ALLOTED WEF MAR 22. ADV 10000. RENT 1800
A14: 9 | B14: VACANT | C14: G/9 | D14: 37347 | E14: 500 | F14: 0 | G14: 12861 | H14: ='MAR 25'!G14 -> 12861 | I14: =G14-H14 -> 0 | J14: =I14*12 -> 0 | K14: 0 | L14: ='MAR 25'!O14 -> 0 | M14: =F14+J14+K14+L14 -> 0 | O14: =M14-N14 -> 0 | Q14: VACATED WEF OCT 24.
A15: 10 | B15: PRAMOD MANDAL | C15: G/10 | D15: 37165 | E15: 500 | F15: 2000 | G15: 3938 | H15: ='MAR 25'!G15 -> 3872 | I15: =G15-H15 -> 66 | J15: =I15*12 -> 792 | K15: 300 | L15: ='MAR 25'!O15 -> 0 | M15: =F15+J15+K15+L15 -> 3092 | N15: 3100 | O15: =M15-N15 -> -8 | Q15: ALLOTED WEF SEP 22. ADV 10000 RENT 2000
A16: 11 | B16: VACANT | C16: 1/1 | D16: 38443 | E16: 0 | F16: 0 | G16: 865 | H16: ='MAR 25'!G16 -> 865 | I16: =G16-H16 -> 0 | J16: =I16*12 -> 0 | K16: 0 | L16: ='MAR 25'!O16 -> 72 | M16: =F16+J16+K16+L16 -> 72 | N16: 72 | O16: =M16-N16 -> 0 | Q16: VACANT FROM DEC 24
A17: 12 | B17: VACANT | C17: 1/2 | D17: 38292 | F17: 0 | G17: 6912 | H17: ='MAR 25'!G17 -> 6883 | I17: =G17-H17 -> 29 | J17: =I17*12 -> 348 | K17: 0 | L17: ='MAR 25'!O17 -> 468 | M17: =F17+J17+K17+L17 -> 816 | N17: 816 | O17: =M17-N17 -> 0 | Q17: VACANT FROM FEB 25.
A18: 13 | B18: VACAMT | C18: 1/3 | D18: 38292 | E18: 500 | F18: 0 | G18: 5655 | H18: ='MAR 25'!G18 -> 5618 | I18: =G18-H18 -> 37 | J18: =I18*12 -> 444 | K18: 0 | L18: ='MAR 25'!O18 -> 24 | M18: =F18+J18+K18+L18 -> 468 | N18: 468 | O18: =M18-N18 -> 0 | Q18: VACANT FROM AUG 24
A19: 14 | B19: ANIL SHARMA | C19: 1/4 | D19: 38292 | E19: 500 | F19: 3000 | G19: 4151 | H19: ='MAR 25'!G19 -> 4101 | I19: =G19-H19 -> 50 | J19: =I19*12 -> 600 | K19: 400 | L19: ='MAR 25'!O19 -> 3856 | M19: =F19+J19+K19+L19 -> 7856 | N19: 0 | O19: =M19-N19 -> 7856 | Q19: ADV 15K.19--5-24. RENT 3000
A20: 15 | B20: VACANT | C20: 1/5 | D20: 37469 | E20: 500 | F20: 0 | G20: 4246 | H20: ='MAR 25'!G20 -> 4245 | I20: =G20-H20 -> 1 | J20: =I20*12 -> 12 | K20: 0 | L20: ='MAR 25'!O20 -> 12 | M20: =F20+J20+K20+L20 -> 24 | N20: 24 | O20: =M20-N20 -> 0 | Q20: VACANT WEF NOV 2023
A21: 16 | B21: SHAILENDRA PANDEY | C21: 1/6 | D21: 37681 | E21: 500 | F21: 3000 | G21: 3551 | H21: ='MAR 25'!G21 -> 3488 | I21: =G21-H21 -> 63 | J21: =I21*12 -> 756 | K21: 400 | L21: ='MAR 25'!O21 -> 25670 | M21: =F21+J21+K21+L21 -> 29826 | N21: 0 | O21: =M21-N21 -> 29826 | Q21: RENT INCREASED WEF MAR 24 FROM 2300. ADV 10000
A22: 17 | B22: BIRENDAR YADAV | C22: 2/1 | D22: 38292 | E22: 500 | F22: 2800 | G22: 816 | H22: ='MAR 25'!G22 -> 779 | I22: =G22-H22 -> 37 | J22: =I22*12 -> 444 | K22: 400 | L22: ='MAR 25'!O22 -> 46024 | M22: =F22+J22+K22+L22 -> 49668 | N22: 10000 | O22: =M22-N22 -> 39668 | Q22: RENT INCREASED WEF DEC 22 FROM 2200. ADV NIL
A23: 18 | B23: HARI SHANKER SHUKLA | C23: 2/2 | D23: 38292 | E23: 500 | F23: 3100 | G23: 1025 | H23: ='MAR 25'!G23 -> 993 | I23: =G23-H23 -> 32 | J23: =I23*12 -> 384 | K23: 400 | L23: ='MAR 25'!O23 -> 11874 | M23: =F23+J23+K23+L23 -> 15758 | N23: 0 | O23: =M23-N23 -> 15758 | Q23: RENT INCRESED WEF JUL 24 FROM 2700. ADV 10000
A24: 19 | B24: SHIV SHANKER PANDEY | C24: 2/3 | D24: 37681 | E24: 500 | F24: 2800 | G24: 5505 | H24: ='MAR 25'!G24 -> 5476 | I24: =G24-H24 -> 29 | J24: =I24*12 -> 348 | K24: 400 | L24: ='MAR 25'!O24 -> -12 | M24: =F24+J24+K24+L24 -> 3536 | N24: 3536 | O24: =M24-N24 -> 0 | Q24: REALLOTED WEF DEC 22. RENT 2800. ADV NIL
A25: 20 | B25: PRAKASH PANDEY | C25: 2/4 | D25: 37681 | E25: 0 | F25: 2800 | G25: 1157 | H25: ='MAR 25'!G25 -> 1082 | I25: =G25-H25 -> 75 | J25: =I25*12 -> 900 | K25: 400 | L25: ='MAR 25'!O25 -> 6580 | M25: =F25+J25+K25+L25 -> 10680 | N25: 4000 | O25: =M25-N25 -> 6680 | Q25: ALLOTED FROM DEC 23. ADV NIL. RENT 2800
A26: 21 | B26: PAPPU | C26: 2/5 | D26: 37681 | E26: 500 | F26: 3000 | G26: 3355 | H26: ='MAR 25'!G26 -> 3310 | I26: =G26-H26 -> 45 | J26: =I26*12 -> 540 | K26: 400 | L26: ='MAR 25'!O26 -> 372 | M26: =F26+J26+K26+L26 -> 4312 | N26: 3500 | O26: =M26-N26 -> 812 | Q26: ALLOTED WEF DEC 24. ADV 10K, RENT 3100
A27: 22 | B27: VACANT | C27: 2/6 | D27: 37681 | E27: 0 | F27: 0 | G27: 5104 | H27: ='MAR 25'!G27 -> 5070 | I27: =G27-H27 -> 34 | J27: =I27*12 -> 408 | K27: 0 | L27: ='MAR 25'!O27 -> 0 | M27: =F27+J27+K27+L27 -> 408 | N27: 408 | O27: =M27-N27 -> 0 | Q27: VACATED WEF OCT 24.
C28: TOTAL | E28: =SUM(E6:E27) -> 7000 | F28: =SUM(F6:F27) -> 36800 | I28: =SUM(I6:I27) -> 711 | J28: =SUM(J6:J27) -> 8532 | K28: =SUM(K6:K27) -> 5200 | L28: =SUM(L6:L27) -> 208502 | M28: =SUM(M6:M27) -> 259034 | N28: =SUM(N6:N27) -> 64198 | O28: =SUM(O6:O27) -> 194836

Sheet MAR 25
A1: SITA DEVI PANDEY HOUSING PROJECT
A2: 11/1B/1 GANPAT RAI KHEMKA LANE LILUAH HOWRAH(W. B.) 711204
A3: FOR THE MONTH OF - MAR 2025 | U3: 44
A4: SNO | B4: NAME | C4: ROOM | D4: DATE OF | E4: ELECTRIC | F4: MTLY | G4: ELECTRIC | K4: MISC | L4: B/F & | M4: TOTAL | N4: AMT | O4: B/F OR | P4: PAYMENT | Q4: REMARKS
C5: NO | D5: ALLOTMENT | E5: SECURITY | F5: RENT | G5: NEW | H5: PRE | I5: TOTAL | J5: COST | K5: RENT | L5: ADV | M5: AMT DUE | N5: PAID | O5: ADV | P5: DATE
A6: 1 | B6: SUNNY PRAJAPATI | C6: G/1 | D6: 38754 | E6: 0 | F6: 2200 | G6: 1479 | H6: ='FEB 25'!G6 -> 1441 | I6: =G6-H6 -> 38 | J6: =I6*12 -> 456 | K6: 300 | L6: ='FEB 25'!O6 -> 15372 | M6: =F6+J6+K6+L6 -> 18328 | N6: 0 | O6: =M6-N6 -> 18328 | Q6: ALLOTED WEF SEP 21. ADV 10000. RENT 2000
A7: 2 | B7: LAXMI SHARMA | C7: G/2 | D7: 37653 | E7: 0 | F7: 1900 | G7: 669 | H7: 661 | I7: =G7-H7 -> 8 | J7: =I7*12 -> 96 | K7: 300 | L7: ='FEB 25'!O7 -> 0 | M7: =F7+J7+K7+L7 -> 2296 | N7: 2296 | O7: =M7-N7 -> 0 | Q7: ALLOTED WEF 07-03-2025. ADV 5K.RENT 1900
A8: 3 | B8: PANKAJ PATEL | C8: G/3 | D8: 37895 | E8: 0 | F8: 2200 | G8: 4470 | H8: ='FEB 25'!G8 -> 4453 | I8: =G8-H8 -> 17 | J8: =I8*12 -> 204 | K8: 300 | L8: ='FEB 25'!O8 -> 20110 | M8: =F8+J8+K8+L8 -> 22814 | N8: 0 | O8: =M8-N8 -> 22814 | Q8: ALLOTED WEF JUL 21. ADV 5K, RENT 2200 FM JUL 24.
A9: 4 | B9: BADRI MANDAL | C9: G/4 | D9: 38292 | E9: 500 | F9: 2000 | G9: 4541 | H9: ='FEB 25'!G9 -> 4489 | I9: =G9-H9 -> 52 | J9: =I9*12 -> 624 | K9: 300 | L9: ='FEB 25'!O9 -> 12094 | M9: =F9+J9+K9+L9 -> 15018 | N9: 0 | O9: =M9-N9 -> 15018 | Q9: ALLOTED WEF 01 DEC 2022. RENT 2000. ADV 5000
A10: 5 | B10: VACANT | C10: G/5 | F10: 0 | G10: 4297 | H10: ='FEB 25'!G10 -> 4286 | I10: =G10-H10 -> 11 | J10: =I10*12 -> 132 | K10: 0 | L10: ='FEB 25'!O10 -> 0 | M10: =F10+J10+K10+L10 -> 132 | N10: 132 | O10: =M10-N10 -> 0 | Q10: VACANT FROM JUL 24
A11: 6 | B11: VIVEK MANDAL | C11: G/6 | D11: 37667 | E11: 500 | F11: 2000 | G11: 2100 | H11: ='FEB 25'!G11 -> 2047 | I11: =G11-H11 -> 53 | J11: =I11*12 -> 636 | K11: 300 | L11: ='FEB 25'!O11 -> 24096 | M11: =F11+J11+K11+L11 -> 27032 | N11: 0 | O11: =M11-N11 -> 27032 | Q11: ALLOTED WEF JUN 24. ADV 4000, RENT 2000
A12: 7 | B12: RAM P SHRESTHA | C12: G/7 | D12: 37773 | E12: 500 | F12: 2200 | G12: 4974 | H12: ='FEB 25'!G12 -> 4953 | I12: =G12-H12 -> 21 | J12: =I12*12 -> 252 | K12: 300 | L12: ='FEB 25'!O12 -> 5072 | M12: =F12+J12+K12+L12 -> 7824 | N12: 0 | O12: =M12-N12 -> 7824 | Q12: ALLOTED WEF SEP 21. ADV 10000. RENT 2000
A13: 8 | B13: AJAY BAG | C13: G/8 | D13: 37469 | E13: 500 | F13: 1800 | G13: 3462 | H13: ='FEB 25'!G13 -> 3365 | I13: =G13-H13 -> 97 | J13: =I13*12 -> 1164 | K13: 300 | L13: ='FEB 25'!O13 -> 16782 | M13: =F13+J13+K13+L13 -> 20046 | N13: 0 | O13: =M13-N13 -> 20046 | Q13: ALLOTED WEF MAR 22. ADV 10000. RENT 1800
A14: 9 | B14: VACANT | C14: G/9 | D14: 37347 | E14: 500 | F14: 0 | G14: 12861 | H14: ='FEB 25'!G14 -> 12861 | I14: =G14-H14 -> 0 | J14: =I14*12 -> 0 | K14: 0 | L14: ='FEB 25'!O14 -> 0 | M14: =F14+J14+K14+L14 -> 0 | N14: 0 | O14: =M14-N14 -> 0 | Q14: VACATED WEF OCT 24.
A15: 10 | B15: PRAMOD MANDAL | C15: G/10 | D15: 37165 | E15: 500 | F15: 2000 | G15: 3872 | H15: ='FEB 25'!G15 -> 3815 | I15: =G15-H15 -> 57 | J15: =I15*12 -> 684 | K15: 300 | L15: ='FEB 25'!O15 -> 0 | M15: =F15+J15+K15+L15 -> 2984 | N15: 2984 | O15: =M15-N15 -> 0 | Q15: ALLOTED WEF SEP 22. ADV 10000 RENT 2000
A16: 11 | B16: VACANT | C16: 1/1 | D16: 38443 | E16: 0 | F16: 0 | G16: 865 | H16: ='FEB 25'!G16 -> 859 | I16: =G16-H16 -> 6 | J16: =I16*12 -> 72 | K16: 0 | L16: ='FEB 25'!O16 -> 0 | M16: =F16+J16+K16+L16 -> 72 | N16: 0 | O16: =M16-N16 -> 72 | Q16: VACANT FROM DEC 24
A17: 12 | B17: VACANT | C17: 1/2 | D17: 38292 | F17: 0 | G17: 6883 | H17: ='FEB 25'!G17 -> 6844 | I17: =G17-H17 -> 39 | J17: =I17*12 -> 468 | K17: 0 | L17: ='FEB 25'!O17 -> 0 | M17: =F17+J17+K17+L17 -> 468 | N17: 0 | O17: =M17-N17 -> 468 | Q17: VACANT FROM FEB 25.
A18: 13 | B18: VACAMT | C18: 1/3 | D18: 38292 | E18: 500 | F18: 0 | G18: 5618 | H18: ='FEB 25'!G18 -> 5616 | I18: =G18-H18 -> 2 | J18: =I18*12 -> 24 | K18: 0 | L18: ='FEB 25'!O18 -> 0 | M18: =F18+J18+K18+L18 -> 24 | N18: 0 | O18: =M18-N18 -> 24 | Q18: VACANT FROM AUG 24
A19: 14 | B19: ANIL SHARMA | C19: 1/4 | D19: 38292 | E19: 500 | F19: 3000 | G19: 4101 | H19: ='FEB 25'!G19 -> 4063 | I19: =G19-H19 -> 38 | J19: =I19*12 -> 456 | K19: 400 | L19: ='FEB 25'!O19 -> 0 | M19: =F19+J19+K19+L19 -> 3856 | N19: 0 | O19: =M19-N19 -> 3856 | Q19: ADV 15K.19--5-24. RENT 3000
A20: 15 | B20: VACANT | C20: 1/5 | D20: 37469 | E20: 500 | F20: 0 | G20: 4245 | H20: ='FEB 25'!G20 -> 4244 | I20: =G20-H20 -> 1 | J20: =I20*12 -> 12 | K20: 0 | L20: ='FEB 25'!O20 -> 0 | M20: =F20+J20+K20+L20 -> 12 | N20: 0 | O20: =M20-N20 -> 12 | Q20: VACANT WEF NOV 2023
A21: 16 | B21: SHAILENDRA PANDEY | C21: 1/6 | D21: 37681 | E21: 500 | F21: 3000 | G21: 3488 | H21: ='FEB 25'!G21 -> 3439 | I21: =G21-H21 -> 49 | J21: =I21*12 -> 588 | K21: 400 | L21: ='FEB 25'!O21 -> 21682 | M21: =F21+J21+K21+L21 -> 25670 | N21: 0 | O21: =M21-N21 -> 25670 | Q21: RENT INCREASED WEF MAR 24 FROM 2300. ADV 10000
A22: 17 | B22: BIRENDAR YADAV | C22: 2/1 | D22: 38292 | E22: 500 | F22: 2800 | G22: 779 | H22: ='FEB 25'!G22 -> 747 | I22: =G22-H22 -> 32 | J22: =I22*12 -> 384 | K22: 400 | L22: ='FEB 25'!O22 -> 42440 | M22: =F22+J22+K22+L22 -> 46024 | N22: 0 | O22: =M22-N22 -> 46024 | Q22: RENT INCREASED WEF DEC 22 FROM 2200. ADV NIL
A23: 18 | B23: HARI SHANKER SHUKLA | C23: 2/2 | D23: 38292 | E23: 500 | F23: 3100 | G23: 993 | H23: 973 | I23: =G23-H23 -> 20 | J23: =I23*12 -> 240 | K23: 400 | L23: ='FEB 25'!O23 -> 14134 | M23: =F23+J23+K23+L23 -> 17874 | N23: 6000 | O23: =M23-N23 -> 11874 | Q23: RENT INCRESED WEF JUL 24 FROM 2700. ADV 10000
A24: 19 | B24: SHIV SHANKER PANDEY | C24: 2/3 | D24: 37681 | E24: 500 | F24: 2800 | G24: 5476 | H24: ='FEB 25'!G24 -> 5452 | I24: =G24-H24 -> 24 | J24: =I24*12 -> 288 | K24: 400 | L24: ='FEB 25'!O24 -> 0 | M24: =F24+J24+K24+L24 -> 3488 | N24: 3500 | O24: =M24-N24 -> -12 | Q24: REALLOTED WEF DEC 22. RENT 2800. ADV NIL
A25: 20 | B25: PRAKASH PANDEY | C25: 2/4 | D25: 37681 | E25: 0 | F25: 2800 | G25: 1082 | H25: ='FEB 25'!G25 -> 1022 | I25: =G25-H25 -> 60 | J25: =I25*12 -> 720 | K25: 400 | L25: ='FEB 25'!O25 -> 2660 | M25: =F25+J25+K25+L25 -> 6580 | N25: 0 | O25: =M25-N25 -> 6580 | Q25: ALLOTED FROM DEC 23. ADV NIL. RENT 2800
A26: 21 | B26: PAPPU | C26: 2/5 | D26: 37681 | E26: 500 | F26: 3000 | G26: 3310 | H26: ='FEB 25'!G26 -> 3267 | I26: =G26-H26 -> 43 | J26: =I26*12 -> 516 | K26: 400 | L26: ='FEB 25'!O26 -> 3456 | M26: =F26+J26+K26+L26 -> 7372 | N26: 7000 | O26: =M26-N26 -> 372 | Q26: ALLOTED WEF DEC 24. ADV 10K, RENT 3100
A27: 22 | B27: VACANT | C27: 2/6 | D27: 37681 | E27: 0 | F27: 0 | G27: 5070 | H27: ='FEB 25'!G27 -> 5070 | I27: =G27-H27 -> 0 | J27: =I27*12 -> 0 | K27: 0 | L27: ='FEB 25'!O27 -> 0 | M27: =F27+J27+K27+L27 -> 0 | N27: 0 | O27: =M27-N27 -> 0 | Q27: VACATED WEF OCT 24.
C28: TOTAL | E28: =SUM(E6:E27) -> 7000 | F28: =SUM(F6:F27) -> 36800 | I28: =SUM(I6:I27) -> 668 | J28: =SUM(J6:J27) -> 8016 | K28: =SUM(K6:K27) -> 5200 | L28: =SUM(L6:L27) -> 177898 | M28: =SUM(M6:M27) -> 227914 | N28: =SUM(N6:N27) -> 21912 | O28: =SUM(O6:O27) -> 206002

Sheet DEC 24
A1: SITA DEVI PANDEY HOUSING PROJECT
A2: 11/1B/1 GANPAT RAI KHEMKA LANE LILUAH HOWRAH(W. B.) 711204
A3: FOR THE MONTH OF - DEC 2024 | U3: 44
A4: SNO | B4: NAME | C4: ROOM | D4: DATE OF | E4: ELECTRIC | F4: MTLY | G4: ELECTRIC | K4: MISC | L4: B/F & | M4: TOTAL | N4: AMT | O4: B/F OR | P4: PAYMENT | Q4: REMARKS
C5: NO | D5: ALLOTMENT | E5: SECURITY | F5: RENT | G5: NEW | H5: PRE | I5: TOTAL | J5: COST | K5: RENT | L5: ADV | M5: AMT DUE | N5: PAID | O5: ADV | P5: DATE
A6: 1 | B6: SUNNY PRAJAPATI | C6: G/1 | D6: 38754 | E6: 0 | F6: 2200 | G6: 1415 | H6: ='NOV 24'!G6 -> 1402 | I6: =G6-H6 -> 13 | J6: =I6*12 -> 156 | K6: 300 | L6: ='NOV 24'!O6 -> 7404 | M6: =F6+J6+K6+L6 -> 10060 | N6: 0 | O6: =M6-N6 -> 10060 | Q6: ALLOTED WEF SEP 21. ADV 10000. RENT 2000
A7: 2 | B7: VACANT | C7: G/2 | D7: 37653 | E7: 0 | F7: 0 | G7: 655 | H7: ='NOV 24'!G7 -> 655 | I7: =G7-H7 -> 0 | J7: =I7*12 -> 0 | K7: 0 | L7: ='NOV 24'!O7 -> 0 | M7: 0 | N7: 0 | O7: =M7-N7 -> 0 | Q7: VACANT FM SEP 24
A8: 3 | B8: PANKAJ PATEL | C8: G/3 | D8: 37895 | E8: 0 | F8: 2200 | G8: 4445 | H8: ='NOV 24'!G8 -> 4444 | I8: =G8-H8 -> 1 | J8: =I8*12 -> 12 | K8: 300 | L8: ='NOV 24'!O8 -> 18502 | M8: =F8+J8+K8+L8 -> 21014 | N8: 3000 | O8: =M8-N8 -> 18014 | Q8: ALLOTED WEF JUL 21. ADV 5K, RENT 2200 FM JUL 24.
A9: 4 | B9: BADRI MANDAL | C9: G/4 | D9: 38292 | E9: 500 | F9: 2000 | G9: 4481 | H9: ='NOV 24'!G9 -> 4476 | I9: =G9-H9 -> 5 | J9: =I9*12 -> 60 | K9: 300 | L9: ='NOV 24'!O9 -> 10038 | M9: =F9+J9+K9+L9 -> 12398 | N9: 0 | O9: =M9-N9 -> 12398 | Q9: ALLOTED WEF 01 DEC 2022. RENT 2000. ADV 5000
A10: 5 | B10: VACANT | C10: G/5 | F10: 0 | G10: 4286 | H10: 4286 | I10: =G10-H10 -> 0 | J10: =I10*12 -> 0 | K10: 0 | L10: ='NOV 24'!O10 -> 0 | M10: =F10+J10+K10+L10 -> 0 | N10: 0 | O10: =M10-N10 -> 0 | Q10: VACANT FROM JUL 24
A11: 6 | B11: VIVEK MANDAL | C11: G/6 | D11: 37667 | E11: 500 | F11: 2000 | G11: 2008 | H11: ='NOV 24'!G11 -> 2005 | I11: =G11-H11 -> 3 | J11: =I11*12 -> 36 | K11: 300 | L11: ='NOV 24'!O11 -> 16692 | M11: =F11+J11+K11+L11 -> 19028 | N11: 0 | O11: =M11-N11 -> 19028 | Q11: ALLOTED WEF JUN 24. ADV 4000, RENT 2000
A12: 7 | B12: RAM P SHRESTHA | C12: G/7 | D12: 37773 | E12: 500 | F12: 2200 | G12: 4947 | H12: ='NOV 24'!G12 -> 4944 | I12: =G12-H12 -> 3 | J12: =I12*12 -> 36 | K12: 300 | L12: ='NOV 24'!O12 -> 200 | M12: =F12+J12+K12+L12 -> 2736 | N12: 0 | O12: =M12-N12 -> 2736 | Q12: ALLOTED WEF SEP 21. ADV 10000. RENT 2000
A13: 8 | B13: AJAY BAG | C13: G/8 | D13: 37469 | E13: 500 | F13: 1800 | G13: 3330 | H13: ='NOV 24'!G13 -> 3325 | I13: =G13-H13 -> 5 | J13: =I13*12 -> 60 | K13: 300 | L13: ='NOV 24'!O13 -> 10002 | M13: =F13+J13+K13+L13 -> 12162 | N13: 0 | O13: =M13-N13 -> 12162 | Q13: ALLOTED WEF MAR 22. ADV 10000. RENT 1800
A14: 9 | B14: VACANT | C14: G/9 | D14: 37347 | E14: 500 | F14: 0 | G14: 12861 | H14: ='NOV 24'!G14 -> 12861 | I14: =G14-H14 -> 0 | J14: =I14*12 -> 0 | K14: 0 | L14: ='NOV 24'!O14 -> 0 | M14: =F14+J14+K14+L14 -> 0 | O14: =M14-N14 -> 0 | Q14: VACATED WEF OCT 24.
A15: 10 | B15: PRAMOD MANDAL | C15: G/10 | D15: 37165 | E15: 500 | F15: 2000 | G15: 3789 | H15: ='NOV 24'!G15 -> 3778 | I15: =G15-H15 -> 11 | J15: =I15*12 -> 132 | K15: 300 | L15: ='NOV 24'!O15 -> 0 | M15: =F15+J15+K15+L15 -> 2432 | N15: 2432 | O15: =M15-N15 -> 0 | Q15: ALLOTED WEF SEP 22. ADV 10000 RENT 2000
A16: 11 | B16: NEW | C16: 1/1 | D16: 38443 | E16: 0 | F16: 2400 | G16: 859 | H16: ='NOV 24'!G16 -> 856 | I16: =G16-H16 -> 3 | J16: =I16*12 -> 36 | K16: 400 | L16: ='NOV 24'!O16 -> 12 | M16: =F16+J16+K16+L16 -> 2848 | N16: 2848 | O16: =M16-N16 -> 0 | Q16: VACATED. ALL DUES CLEAR
A17: 12 | B17: RAKESH AGARWAL | C17: 1/2 | D17: 38292 | F17: 3100 | G17: 6842 | H17: ='NOV 24'!G17 -> 6835 | I17: =G17-H17 -> 7 | J17: =I17*12 -> 84 | K17: 400 | L17: ='NOV 24'!O17 -> 9888 | M17: =F17+J17+K17+L17 -> 13472 | N17: 0 | O17: =M17-N17 -> 13472 | Q17: ALLOTED WEF JUL 24. ADV 10K. RENT 3100
A18: 13 | B18: VACAMT | C18: 1/3 | D18: 38292 | E18: 500 | F18: 0 | G18: 5616 | H18: ='NOV 24'!G18 -> 5616 | I18: =G18-H18 -> 0 | J18: =I18*12 -> 0 | K18: 0 | L18: ='NOV 24'!O18 -> 0 | M18: =F18+J18+K18+L18 -> 0 | N18: 0 | O18: =M18-N18 -> 0 | Q18: VACANT FROM AUG 24
A19: 14 | B19: ANIL SHARMA | C19: 1/4 | D19: 38292 | E19: 500 | F19: 3000 | G19: 4032 | H19: ='NOV 24'!G19 -> 4026 | I19: =G19-H19 -> 6 | J19: =I19*12 -> 72 | K19: 400 | L19: ='NOV 24'!O19 -> 0 | M19: =F19+J19+K19+L19 -> 3472 | N19: 3480 | O19: =M19-N19 -> -8 | Q19: ADV 15K.19--5-24. RENT 3000
A20: 15 | B20: VACANT | C20: 1/5 | D20: 37469 | E20: 500 | F20: 0 | G20: 4244 | H20: ='NOV 24'!G20 -> 4244 | I20: =G20-H20 -> 0 | J20: =I20*12 -> 0 | K20: 0 | L20: ='NOV 24'!O20 -> 0 | M20: =F20+J20+K20+L20 -> 0 | N20: 0 | O20: =M20-N20 -> 0 | Q20: VACANT WEF NOV 2023
A21: 16 | B21: SHAILENDRA PANDEY | C21: 1/6 | D21: 37681 | E21: 500 | F21: 3000 | G21: 3381 | H21: ='NOV 24'!G21 -> 3368 | I21: =G21-H21 -> 13 | J21: =I21*12 -> 156 | K21: 400 | L21: ='NOV 24'!O21 -> 20630 | M21: =F21+J21+K21+L21 -> 24186 | N21: 5000 | O21: =M21-N21 -> 19186 | Q21: RENT INCREASED WEF MAR 24 FROM 2300. ADV 10000
A22: 17 | B22: BIRENDAR YADAV | C22: 2/1 | D22: 38292 | E22: 500 | F22: 2800 | G22: 712 | H22: ='NOV 24'!G22 -> 702 | I22: =G22-H22 -> 10 | J22: =I22*12 -> 120 | K22: 400 | L22: ='NOV 24'!O22 -> 44300 | M22: =F22+J22+K22+L22 -> 47620 | N22: 7000 | O22: =M22-N22 -> 40620 | Q22: RENT INCREASED WEF DEC 22 FROM 2200. ADV NIL
A23: 18 | B23: HARI SHANKER SHUKLA | C23: 2/2 | D23: 38292 | E23: 500 | F23: 3100 | G23: 976 | H23: ='NOV 24'!G23 -> 976 | I23: =G23-H23 -> 0 | J23: =I23*12 -> 0 | K23: 400 | L23: ='NOV 24'!O23 -> 13634 | M23: =F23+J23+K23+L23 -> 17134 | N23: 0 | O23: =M23-N23 -> 17134 | Q23: RENT INCRESED WEF JUL 24 FROM 2700. ADV 10000
A24: 19 | B24: SHIV SHANKER PANDEY | C24: 2/3 | D24: 37681 | E24: 500 | F24: 2800 | G24: 5432 | H24: ='NOV 24'!G24 -> 5424 | I24: =G24-H24 -> 8 | J24: =I24*12 -> 96 | K24: 400 | L24: ='NOV 24'!O24 -> 0 | M24: =F24+J24+K24+L24 -> 3296 | N24: 3296 | O24: =M24-N24 -> 0 | Q24: REALLOTED WEF DEC 22. RENT 2800. ADV NIL
A25: 20 | B25: PRAKASH PANDEY | C25: 2/4 | D25: 37681 | E25: 0 | F25: 2800 | G25: 956 | H25: ='NOV 24'!G25 -> 940 | I25: =G25-H25 -> 16 | J25: =I25*12 -> 192 | K25: 400 | L25: ='NOV 24'!O25 -> 7076 | M25: =F25+J25+K25+L25 -> 10468 | N25: 5000 | O25: =M25-N25 -> 5468 | Q25: ALLOTED FROM DEC 23. ADV NIL. RENT 2800
A26: 21 | B26: VACANT | C26: 2/5 | D26: 37681 | E26: 500 | F26: 0 | G26: 3254 | H26: ='NOV 24'!G26 -> 3254 | I26: =G26-H26 -> 0 | J26: =I26*12 -> 0 | K26: 0 | L26: ='NOV 24'!O26 -> 0 | M26: =F26+J26+K26+L26 -> 0 | N26: 0 | O26: =M26-N26 -> 0 | Q26: VACATED WEF NOV 23.
A27: 22 | B27: VACANT | C27: 2/6 | D27: 37681 | E27: 0 | F27: 0 | G27: 5051 | H27: ='NOV 24'!G27 -> 5051 | I27: =G27-H27 -> 0 | J27: =I27*12 -> 0 | K27: 0 | L27: ='NOV 24'!O27 -> 0 | M27: =F27+J27+K27+L27 -> 0 | N27: 0 | O27: =M27-N27 -> 0 | Q27: VACATED WEF OCT 24.
C28: TOTAL | E28: =SUM(E6:E27) -> 7000 | F28: =SUM(F6:F27) -> 37400 | I28: =SUM(I6:I27) -> 104 | J28: =SUM(J6:J27) -> 1248 | K28: =SUM(K6:K27) -> 5300 | L28: =SUM(L6:L27) -> 158378 | M28: =SUM(M6:M27) -> 202326 | N28: =SUM(N6:N27) -> 32056 | O28: =SUM(O6:O27) -> 170270

Sheet FEB 25
A1: SITA DEVI PANDEY HOUSING PROJECT
A2: 11/1B/1 GANPAT RAI KHEMKA LANE LILUAH HOWRAH(W. B.) 711204
A3: FOR THE MONTH OF - JAN 2025 | U3: 44
A4: SNO | B4: NAME | C4: ROOM | D4: DATE OF | E4: ELECTRIC | F4: MTLY | G4: ELECTRIC | K4: MISC | L4: B/F & | M4: TOTAL | N4: AMT | O4: B/F OR | P4: PAYMENT | Q4: REMARKS
C5: NO | D5: ALLOTMENT | E5: SECURITY | F5: RENT | G5: NEW | H5: PRE | I5: TOTAL | J5: COST | K5: RENT | L5: ADV | M5: AMT DUE | N5: PAID | O5: ADV | P5: DATE
A6: 1 | B6: SUNNY PRAJAPATI | C6: G/1 | D6: 38754 | E6: 0 | F6: 2200 | G6: 1441 | H6: ='JAN 25'!G6 -> 1432 | I6: =G6-H6 -> 9 | J6: =I6*12 -> 108 | K6: 300 | L6: ='JAN 25'!O6 -> 12764 | M6: =F6+J6+K6+L6 -> 15372 | N6: 0 | O6: =M6-N6 -> 15372 | Q6: ALLOTED WEF SEP 21. ADV 10000. RENT 2000
A7: 2 | B7: VACANT | C7: G/2 | D7: 37653 | E7: 0 | F7: 0 | G7: 655 | H7: ='JAN 25'!G7 -> 655 | I7: =G7-H7 -> 0 | J7: =I7*12 -> 0 | K7: 0 | L7: ='JAN 25'!O7 -> 0 | M7: 0 | N7: 0 | O7: =M7-N7 -> 0 | Q7: VACANT FM SEP 24
A8: 3 | B8: PANKAJ PATEL | C8: G/3 | D8: 37895 | E8: 0 | F8: 2200 | G8: 4453 | H8: ='JAN 25'!G8 -> 4448 | I8: =G8-H8 -> 5 | J8: =I8*12 -> 60 | K8: 300 | L8: ='JAN 25'!O8 -> 17550 | M8: =F8+J8+K8+L8 -> 20110 | N8: 0 | O8: =M8-N8 -> 20110 | Q8: ALLOTED WEF JUL 21. ADV 5K, RENT 2200 FM JUL 24.
A9: 4 | B9: BADRI MANDAL | C9: G/4 | D9: 38292 | E9: 500 | F9: 2000 | G9: 4489 | H9: ='JAN 25'!G9 -> 4488 | I9: =G9-H9 -> 1 | J9: =I9*12 -> 12 | K9: 300 | L9: ='JAN 25'!O9 -> 9782 | M9: =F9+J9+K9+L9 -> 12094 | N9: 0 | O9: =M9-N9 -> 12094 | Q9: ALLOTED WEF 01 DEC 2022. RENT 2000. ADV 5000
A10: 5 | B10: VACANT | C10: G/5 | F10: 0 | G10: 4286 | H10: ='JAN 25'!G10 -> 4286 | I10: =G10-H10 -> 0 | J10: =I10*12 -> 0 | K10: 0 | L10: ='JAN 25'!O10 -> 0 | M10: =F10+J10+K10+L10 -> 0 | N10: 0 | O10: =M10-N10 -> 0 | Q10: VACANT FROM JUL 24
A11: 6 | B11: VIVEK MANDAL | C11: G/6 | D11: 37667 | E11: 500 | F11: 2000 | G11: 2047 | H11: ='JAN 25'!G11 -> 2016 | I11: =G11-H11 -> 31 | J11: =I11*12 -> 372 | K11: 300 | L11: ='JAN 25'!O11 -> 21424 | M11: =F11+J11+K11+L11 -> 24096 | N11: 0 | O11: =M11-N11 -> 24096 | Q11: ALLOTED WEF JUN 24. ADV 4000, RENT 2000
A12: 7 | B12: RAM P SHRESTHA | C12: G/7 | D12: 37773 | E12: 500 | F12: 2200 | G12: 4953 | H12: ='JAN 25'!G12 -> 4949 | I12: =G12-H12 -> 4 | J12: =I12*12 -> 48 | K12: 300 | L12: ='JAN 25'!O12 -> 2524 | M12: =F12+J12+K12+L12 -> 5072 | N12: 0 | O12: =M12-N12 -> 5072 | Q12: ALLOTED WEF SEP 21. ADV 10000. RENT 2000
A13: 8 | B13: AJAY BAG | C13: G/8 | D13: 37469 | E13: 500 | F13: 1800 | G13: 3365 | H13: ='JAN 25'!G13 -> 3338 | I13: =G13-H13 -> 27 | J13: =I13*12 -> 324 | K13: 300 | L13: ='JAN 25'!O13 -> 14358 | M13: =F13+J13+K13+L13 -> 16782 | N13: 0 | O13: =M13-N13 -> 16782 | Q13: ALLOTED WEF MAR 22. ADV 10000. RENT 1800
A14: 9 | B14: VACANT | C14: G/9 | D14: 37347 | E14: 500 | F14: 0 | G14: 12861 | H14: ='JAN 25'!G14 -> 12861 | I14: =G14-H14 -> 0 | J14: =I14*12 -> 0 | K14: 0 | L14: ='JAN 25'!O14 -> 0 | M14: =F14+J14+K14+L14 -> 0 | N14: 0 | O14: =M14-N14 -> 0 | Q14: VACATED WEF OCT 24.
A15: 10 | B15: PRAMOD MANDAL | C15: G/10 | D15: 37165 | E15: 500 | F15: 2000 | G15: 3815 | H15: ='JAN 25'!G15 -> 3800 | I15: =G15-H15 -> 15 | J15: =I15*12 -> 180 | K15: 300 | L15: ='JAN 25'!O15 -> 0 | M15: =F15+J15+K15+L15 -> 2480 | N15: 2480 | O15: =M15-N15 -> 0 | Q15: ALLOTED WEF SEP 22. ADV 10000 RENT 2000
A16: 11 | B16: VACANT | C16: 1/1 | D16: 38443 | E16: 0 | F16: 0 | G16: 859 | H16: ='JAN 25'!G16 -> 859 | I16: =G16-H16 -> 0 | J16: =I16*12 -> 0 | K16: 0 | L16: ='JAN 25'!O16 -> 0 | M16: =F16+J16+K16+L16 -> 0 | N16: 0 | O16: =M16-N16 -> 0 | Q16: VACANT FROM DEC 24
A17: 12 | B17: RAKESH AGARWAL | C17: 1/2 | D17: 38292 | F17: 3100 | G17: 6844 | H17: ='JAN 25'!G17 -> 6844 | I17: =G17-H17 -> 0 | J17: =I17*12 -> 0 | K17: 400 | L17: ='JAN 25'!O17 -> 16996 | M17: =F17+J17+K17+L17 -> 20496 | N17: 20496 | O17: =M17-N17 -> 0 | Q17: VACANT FROM FEB 25.
A18: 13 | B18: VACAMT | C18: 1/3 | D18: 38292 | E18: 500 | F18: 0 | G18: 5616 | H18: ='JAN 25'!G18 -> 5616 | I18: =G18-H18 -> 0 | J18: =I18*12 -> 0 | K18: 0 | L18: ='JAN 25'!O18 -> 0 | M18: =F18+J18+K18+L18 -> 0 | N18: 0 | O18: =M18-N18 -> 0 | Q18: VACANT FROM AUG 24
A19: 14 | B19: ANIL SHARMA | C19: 1/4 | D19: 38292 | E19: 500 | F19: 3000 | G19: 4063 | H19: ='JAN 25'!G19 -> 4039 | I19: =G19-H19 -> 24 | J19: =I19*12 -> 288 | K19: 400 | L19: ='JAN 25'!O19 -> -4 | M19: =F19+J19+K19+L19 -> 3684 | N19: 3684 | O19: =M19-N19 -> 0 | Q19: ADV 15K.19--5-24. RENT 3000
A20: 15 | B20: VACANT | C20: 1/5 | D20: 37469 | E20: 500 | F20: 0 | G20: 4244 | H20: ='JAN 25'!G20 -> 4244 | I20: =G20-H20 -> 0 | J20: =I20*12 -> 0 | K20: 0 | L20: ='JAN 25'!O20 -> 0 | M20: =F20+J20+K20+L20 -> 0 | N20: 0 | O20: =M20-N20 -> 0 | Q20: VACANT WEF NOV 2023
A21: 16 | B21: SHAILENDRA PANDEY | C21: 1/6 | D21: 37681 | E21: 500 | F21: 3000 | G21: 3439 | H21: ='JAN 25'!G21 -> 3416 | I21: =G21-H21 -> 23 | J21: =I21*12 -> 276 | K21: 400 | L21: ='JAN 25'!O21 -> 23006 | M21: =F21+J21+K21+L21 -> 26682 | N21: 5000 | O21: =M21-N21 -> 21682 | Q21: RENT INCREASED WEF MAR 24 FROM 2300. ADV 10000
A22: 17 | B22: BIRENDAR YADAV | C22: 2/1 | D22: 38292 | E22: 500 | F22: 2800 | G22: 747 | H22: ='JAN 25'!G22 -> 729 | I22: =G22-H22 -> 18 | J22: =I22*12 -> 216 | K22: 400 | L22: ='JAN 25'!O22 -> 44024 | M22: =F22+J22+K22+L22 -> 47440 | N22: 5000 | O22: =M22-N22 -> 42440 | Q22: RENT INCREASED WEF DEC 22 FROM 2200. ADV NIL
A23: 18 | B23: HARI SHANKER SHUKLA | C23: 2/2 | D23: 38292 | E23: 500 | F23: 3100 | G23: 976 | H23: ='JAN 25'!G23 -> 976 | I23: =G23-H23 -> 0 | J23: =I23*12 -> 0 | K23: 400 | L23: ='JAN 25'!O23 -> 20634 | M23: =F23+J23+K23+L23 -> 24134 | N23: 10000 | O23: =M23-N23 -> 14134 | Q23: RENT INCRESED WEF JUL 24 FROM 2700. ADV 10000
A24: 19 | B24: SHIV SHANKER PANDEY | C24: 2/3 | D24: 37681 | E24: 500 | F24: 2800 | G24: 5452 | H24: ='JAN 25'!G24 -> 5441 | I24: =G24-H24 -> 11 | J24: =I24*12 -> 132 | K24: 400 | L24: ='JAN 25'!O24 -> -2 | M24: =F24+J24+K24+L24 -> 3330 | N24: 3330 | O24: =M24-N24 -> 0 | Q24: REALLOTED WEF DEC 22. RENT 2800. ADV NIL
A25: 20 | B25: PRAKASH PANDEY | C25: 2/4 | D25: 37681 | E25: 0 | F25: 2800 | G25: 1022 | H25: ='JAN 25'!G25 -> 986 | I25: =G25-H25 -> 36 | J25: =I25*12 -> 432 | K25: 400 | L25: ='JAN 25'!O25 -> 4028 | M25: =F25+J25+K25+L25 -> 7660 | N25: 5000 | O25: =M25-N25 -> 2660 | Q25: ALLOTED FROM DEC 23. ADV NIL. RENT 2800
A26: 21 | B26: PAPPU | C26: 2/5 | D26: 37681 | E26: 500 | F26: 3000 | G26: 3267 | H26: ='JAN 25'!G26 -> 3257 | I26: =G26-H26 -> 10 | J26: =I26*12 -> 120 | K26: 400 | L26: ='JAN 25'!O26 -> -64 | M26: =F26+J26+K26+L26 -> 3456 | N26: 0 | O26: =M26-N26 -> 3456 | Q26: ALLOTED WEF DEC 24. ADV 10K, RENT 3100
A27: 22 | B27: VACANT | C27: 2/6 | D27: 37681 | E27: 0 | F27: 0 | G27: 5070 | H27: ='JAN 25'!G27 -> 5070 | I27: =G27-H27 -> 0 | J27: =I27*12 -> 0 | K27: 0 | L27: ='JAN 25'!O27 -> 0 | M27: =F27+J27+K27+L27 -> 0 | N27: 0 | O27: =M27-N27 -> 0 | Q27: VACATED WEF OCT 24.
C28: TOTAL | E28: =SUM(E6:E27) -> 7000 | F28: =SUM(F6:F27) -> 38000 | I28: =SUM(I6:I27) -> 214 | J28: =SUM(J6:J27) -> 2568 | K28: =SUM(K6:K27) -> 5300 | L28: =SUM(L6:L27) -> 187020 | M28: =SUM(M6:M27) -> 232888 | N28: =SUM(N6:N27) -> 54990 | O28: =SUM(O6:O27) -> 177898

Sheet JAN 25
A1: SITA DEVI PANDEY HOUSING PROJECT
A2: 11/1B/1 GANPAT RAI KHEMKA LANE LILUAH HOWRAH(W. B.) 711204
A3: FOR THE MONTH OF - JAN 2025 | U3: 44
A4: SNO | B4: NAME | C4: ROOM | D4: DATE OF | E4: ELECTRIC | F4: MTLY | G4: ELECTRIC | K4: MISC | L4: B/F & | M4: TOTAL | N4: AMT | O4: B/F OR | P4: PAYMENT | Q4: REMARKS
C5: NO | D5: ALLOTMENT | E5: SECURITY | F5: RENT | G5: NEW | H5: PRE | I5: TOTAL | J5: COST | K5: RENT | L5: ADV | M5: AMT DUE | N5: PAID | O5: ADV | P5: DATE
A6: 1 | B6: SUNNY PRAJAPATI | C6: G/1 | D6: 38754 | E6: 0 | F6: 2200 | G6: 1432 | H6: ='DEC 24'!G6 -> 1415 | I6: =G6-H6 -> 17 | J6: =I6*12 -> 204 | K6: 300 | L6: ='DEC 24'!O6 -> 10060 | M6: =F6+J6+K6+L6 -> 12764 | N6: 0 | O6: =M6-N6 -> 12764 | Q6: ALLOTED WEF SEP 21. ADV 10000. RENT 2000
A7: 2 | B7: VACANT | C7: G/2 | D7: 37653 | E7: 0 | F7: 0 | G7: 655 | H7: ='DEC 24'!G7 -> 655 | I7: =G7-H7 -> 0 | J7: =I7*12 -> 0 | K7: 0 | L7: ='DEC 24'!O7 -> 0 | M7: 0 | N7: 0 | O7: =M7-N7 -> 0 | Q7: VACANT FM SEP 24
A8: 3 | B8: PANKAJ PATEL | C8: G/3 | D8: 37895 | E8: 0 | F8: 2200 | G8: 4448 | H8: ='DEC 24'!G8 -> 4445 | I8: =G8-H8 -> 3 | J8: =I8*12 -> 36 | K8: 300 | L8: ='DEC 24'!O8 -> 18014 | M8: =F8+J8+K8+L8 -> 20550 | N8: 3000 | O8: =M8-N8 -> 17550 | Q8: ALLOTED WEF JUL 21. ADV 5K, RENT 2200 FM JUL 24.
A9: 4 | B9: BADRI MANDAL | C9: G/4 | D9: 38292 | E9: 500 | F9: 2000 | G9: 4488 | H9: ='DEC 24'!G9 -> 4481 | I9: =G9-H9 -> 7 | J9: =I9*12 -> 84 | K9: 300 | L9: ='DEC 24'!O9 -> 12398 | M9: =F9+J9+K9+L9 -> 14782 | N9: 5000 | O9: =M9-N9 -> 9782 | Q9: ALLOTED WEF 01 DEC 2022. RENT 2000. ADV 5000
A10: 5 | B10: VACANT | C10: G/5 | F10: 0 | G10: 4286 | H10: ='DEC 24'!G10 -> 4286 | I10: =G10-H10 -> 0 | J10: =I10*12 -> 0 | K10: 0 | L10: ='DEC 24'!O10 -> 0 | M10: =F10+J10+K10+L10 -> 0 | N10: 0 | O10: =M10-N10 -> 0 | Q10: VACANT FROM JUL 24
A11: 6 | B11: VIVEK MANDAL | C11: G/6 | D11: 37667 | E11: 500 | F11: 2000 | G11: 2016 | H11: ='DEC 24'!G11 -> 2008 | I11: =G11-H11 -> 8 | J11: =I11*12 -> 96 | K11: 300 | L11: ='DEC 24'!O11 -> 19028 | M11: =F11+J11+K11+L11 -> 21424 | N11: 0 | O11: =M11-N11 -> 21424 | Q11: ALLOTED WEF JUN 24. ADV 4000, RENT 2000
A12: 7 | B12: RAM P SHRESTHA | C12: G/7 | D12: 37773 | E12: 500 | F12: 2200 | G12: 4949 | H12: ='DEC 24'!G12 -> 4947 | I12: =G12-H12 -> 2 | J12: =I12*12 -> 24 | K12: 300 | L12: ='DEC 24'!O12 -> 2736 | M12: =F12+J12+K12+L12 -> 5260 | N12: 2736 | O12: =M12-N12 -> 2524 | Q12: ALLOTED WEF SEP 21. ADV 10000. RENT 2000
A13: 8 | B13: AJAY BAG | C13: G/8 | D13: 37469 | E13: 500 | F13: 1800 | G13: 3338 | H13: ='DEC 24'!G13 -> 3330 | I13: =G13-H13 -> 8 | J13: =I13*12 -> 96 | K13: 300 | L13: ='DEC 24'!O13 -> 12162 | M13: =F13+J13+K13+L13 -> 14358 | N13: 0 | O13: =M13-N13 -> 14358 | Q13: ALLOTED WEF MAR 22. ADV 10000. RENT 1800
A14: 9 | B14: VACANT | C14: G/9 | D14: 37347 | E14: 500 | F14: 0 | G14: 12861 | H14: ='DEC 24'!G14 -> 12861 | I14: =G14-H14 -> 0 | J14: =I14*12 -> 0 | K14: 0 | L14: ='DEC 24'!O14 -> 0 | M14: =F14+J14+K14+L14 -> 0 | O14: =M14-N14 -> 0 | Q14: VACATED WEF OCT 24.
A15: 10 | B15: PRAMOD MANDAL | C15: G/10 | D15: 37165 | E15: 500 | F15: 2000 | G15: 3800 | H15: ='DEC 24'!G15 -> 3789 | I15: =G15-H15 -> 11 | J15: =I15*12 -> 132 | K15: 300 | L15: ='DEC 24'!O15 -> 0 | M15: =F15+J15+K15+L15 -> 2432 | N15: 2432 | O15: =M15-N15 -> 0 | Q15: ALLOTED WEF SEP 22. ADV 10000 RENT 2000
A16: 11 | B16: VACANT | C16: 1/1 | D16: 38443 | E16: 0 | F16: 0 | G16: 859 | H16: ='DEC 24'!G16 -> 859 | I16: =G16-H16 -> 0 | J16: =I16*12 -> 0 | K16: 0 | L16: ='DEC 24'!O16 -> 0 | M16: =F16+J16+K16+L16 -> 0 | N16: 0 | O16: =M16-N16 -> 0 | Q16: VACANT FROM DEC 24
A17: 12 | B17: RAKESH AGARWAL | C17: 1/2 | D17: 38292 | F17: 3100 | G17: 6844 | H17: ='DEC 24'!G17 -> 6842 | I17: =G17-H17 -> 2 | J17: =I17*12 -> 24 | K17: 400 | L17: ='DEC 24'!O17 -> 13472 | M17: =F17+J17+K17+L17 -> 16996 | N17: 0 | O17: =M17-N17 -> 16996 | Q17: ALLOTED WEF JUL 24. ADV 10K. RENT 3100
A18: 13 | B18: VACAMT | C18: 1/3 | D18: 38292 | E18: 500 | F18: 0 | G18: 5616 | H18: ='DEC 24'!G18 -> 5616 | I18: =G18-H18 -> 0 | J18: =I18*12 -> 0 | K18: 0 | L18: ='DEC 24'!O18 -> 0 | M18: =F18+J18+K18+L18 -> 0 | N18: 0 | O18: =M18-N18 -> 0 | Q18: VACANT FROM AUG 24
A19: 14 | B19: ANIL SHARMA | C19: 1/4 | D19: 38292 | E19: 500 | F19: 3000 | G19: 4039 | H19: ='DEC 24'!G19 -> 4032 | I19: =G19-H19 -> 7 | J19: =I19*12 -> 84 | K19: 400 | L19: ='DEC 24'!O19 -> -8 | M19: =F19+J19+K19+L19 -> 3476 | N19: 3480 | O19: =M19-N19 -> -4 | Q19: ADV 15K.19--5-24. RENT 3000
A20: 15 | B20: VACANT | C20: 1/5 | D20: 37469 | E20: 500 | F20: 0 | G20: 4244 | H20: ='DEC 24'!G20 -> 4244 | I20: =G20-H20 -> 0 | J20: =I20*12 -> 0 | K20: 0 | L20: ='DEC 24'!O20 -> 0 | M20: =F20+J20+K20+L20 -> 0 | N20: 0 | O20: =M20-N20 -> 0 | Q20: VACANT WEF NOV 2023
A21: 16 | B21: SHAILENDRA PANDEY | C21: 1/6 | D21: 37681 | E21: 500 | F21: 3000 | G21: 3416 | H21: ='DEC 24'!G21 -> 3381 | I21: =G21-H21 -> 35 | J21: =I21*12 -> 420 | K21: 400 | L21: ='DEC 24'!O21 -> 19186 | M21: =F21+J21+K21+L21 -> 23006 | N21: 0 | O21: =M21-N21 -> 23006 | Q21: RENT INCREASED WEF MAR 24 FROM 2300. ADV 10000
A22: 17 | B22: BIRENDAR YADAV | C22: 2/1 | D22: 38292 | E22: 500 | F22: 2800 | G22: 729 | H22: ='DEC 24'!G22 -> 712 | I22: =G22-H22 -> 17 | J22: =I22*12 -> 204 | K22: 400 | L22: ='DEC 24'!O22 -> 40620 | M22: =F22+J22+K22+L22 -> 44024 | N22: 0 | O22: =M22-N22 -> 44024 | Q22: RENT INCREASED WEF DEC 22 FROM 2200. ADV NIL
A23: 18 | B23: HARI SHANKER SHUKLA | C23: 2/2 | D23: 38292 | E23: 500 | F23: 3100 | G23: 976 | H23: ='DEC 24'!G23 -> 976 | I23: =G23-H23 -> 0 | J23: =I23*12 -> 0 | K23: 400 | L23: ='DEC 24'!O23 -> 17134 | M23: =F23+J23+K23+L23 -> 20634 | N23: 0 | O23: =M23-N23 -> 20634 | Q23: RENT INCRESED WEF JUL 24 FROM 2700. ADV 10000
A24: 19 | B24: SHIV SHANKER PANDEY | C24: 2/3 | D24: 37681 | E24: 500 | F24: 2800 | G24: 5441 | H24: ='DEC 24'!G24 -> 5432 | I24: =G24-H24 -> 9 | J24: =I24*12 -> 108 | K24: 400 | L24: ='DEC 24'!O24 -> 0 | M24: =F24+J24+K24+L24 -> 3308 | N24: 3310 | O24: =M24-N24 -> -2 | Q24: REALLOTED WEF DEC 22. RENT 2800. ADV NIL
A25: 20 | B25: PRAKASH PANDEY | C25: 2/4 | D25: 37681 | E25: 0 | F25: 2800 | G25: 986 | H25: ='DEC 24'!G25 -> 956 | I25: =G25-H25 -> 30 | J25: =I25*12 -> 360 | K25: 400 | L25: ='DEC 24'!O25 -> 5468 | M25: =F25+J25+K25+L25 -> 9028 | N25: 5000 | O25: =M25-N25 -> 4028 | Q25: ALLOTED FROM DEC 23. ADV NIL. RENT 2800
A26: 21 | B26: PAPPU | C26: 2/5 | D26: 37681 | E26: 500 | F26: 3000 | G26: 3257 | H26: ='DEC 24'!G26 -> 3254 | I26: =G26-H26 -> 3 | J26: =I26*12 -> 36 | K26: 400 | L26: ='DEC 24'!O26 -> 0 | M26: =F26+J26+K26+L26 -> 3436 | N26: 3500 | O26: =M26-N26 -> -64 | Q26: ALLOTED WEF DEC 24. ADV 10K, RENT 3100
A27: 22 | B27: VACANT | C27: 2/6 | D27: 37681 | E27: 0 | F27: 0 | G27: 5070 | H27: ='DEC 24'!G27 -> 5051 | I27: =G27-H27 -> 19 | J27: =I27*12 -> 228 | K27: 0 | L27: ='DEC 24'!O27 -> 0 | M27: =F27+J27+K27+L27 -> 228 | N27: 228 | O27: =M27-N27 -> 0 | Q27: VACATED WEF OCT 24.
C28: TOTAL | E28: =SUM(E6:E27) -> 7000 | F28: =SUM(F6:F27) -> 38000 | I28: =SUM(I6:I27) -> 178 | J28: =SUM(J6:J27) -> 2136 | K28: =SUM(K6:K27) -> 5300 | L28: =SUM(L6:L27) -> 170270 | M28: =SUM(M6:M27) -> 215706 | N28: =SUM(N6:N27) -> 28686 | O28: =SUM(O6:O27) -> 187020

Sheet NOV 24
A1: SITA DEVI PANDEY HOUSING PROJECT
A2: 11/1B/1 GANPAT RAI KHEMKA LANE LILUAH HOWRAH(W. B.) 711204
A3: FOR THE MONTH OF - NOV 2024 | U3: 44
A4: SNO | B4: NAME | C4: ROOM | D4: DATE OF | E4: ELECTRIC | F4: MTLY | G4: ELECTRIC | K4: MISC | L4: B/F & | M4: TOTAL | N4: AMT | O4: B/F OR | P4: PAYMENT | Q4: REMARKS
C5: NO | D5: ALLOTMENT | E5: SECURITY | F5: RENT | G5: NEW | H5: PRE | I5: TOTAL | J5: COST | K5: RENT | L5: ADV | M5: AMT DUE | N5: PAID | O5: ADV | P5: DATE
A6: 1 | B6: SUNNY PRAJAPATI | C6: G/1 | D6: 38754 | E6: 0 | F6: 2200 | G6: 1402 | H6: ='OCT 24'!G6 -> 1382 | I6: =G6-H6 -> 20 | J6: =I6*12 -> 240 | K6: 300 | L6: ='OCT 24'!O6 -> 4664 | M6: =F6+J6+K6+L6 -> 7404 | N6: 0 | O6: =M6-N6 -> 7404 | Q6: ALLOTED WEF SEP 21. ADV 10000. RENT 2000
A7: 2 | B7: VACANT | C7: G/2 | D7: 37653 | E7: 0 | F7: 0 | G7: 655 | H7: ='OCT 24'!G7 -> 655 | I7: =G7-H7 -> 0 | J7: =I7*12 -> 0 | K7: 0 | L7: ='OCT 24'!O7 -> 0 | M7: 0 | N7: 0 | O7: =M7-N7 -> 0 | Q7: VACANT FM SEP 24
A8: 3 | B8: PANKAJ PATEL | C8: G/3 | D8: 37895 | E8: 0 | F8: 2200 | G8: 4444 | H8: ='OCT 24'!G8 -> 4441 | I8: =G8-H8 -> 3 | J8: =I8*12 -> 36 | K8: 300 | L8: ='OCT 24'!O8 -> 15966 | M8: =F8+J8+K8+L8 -> 18502 | N8: 0 | O8: =M8-N8 -> 18502 | Q8: ALLOTED WEF JUL 21. ADV 5K, RENT 2200 FM JUL 24.
A9: 4 | B9: BADRI MANDAL | C9: G/4 | D9: 38292 | E9: 500 | F9: 2000 | G9: 4476 | H9: ='OCT 24'!G9 -> 4452 | I9: =G9-H9 -> 24 | J9: =I9*12 -> 288 | K9: 300 | L9: ='OCT 24'!O9 -> 12450 | M9: =F9+J9+K9+L9 -> 15038 | N9: 5000 | O9: =M9-N9 -> 10038 | Q9: ALLOTED WEF 01 DEC 2022. RENT 2000. ADV 5000
A10: 5 | B10: VACANT | C10: G/5 | F10: 0 | G10: 4279 | H10: ='OCT 24'!G10 -> 4279 | I10: =G10-H10 -> 0 | J10: =I10*12 -> 0 | K10: 0 | L10: ='OCT 24'!O10 -> 0 | M10: =F10+J10+K10+L10 -> 0 | N10: 0 | O10: =M10-N10 -> 0 | Q10: VACANT FROM JUL 24
A11: 6 | B11: VIVEK MANDAL | C11: G/6 | D11: 37667 | E11: 500 | F11: 2000 | G11: 2005 | H11: ='OCT 24'!G11 -> 1967 | I11: =G11-H11 -> 38 | J11: =I11*12 -> 456 | K11: 300 | L11: ='OCT 24'!O11 -> 13936 | M11: =F11+J11+K11+L11 -> 16692 | N11: 0 | O11: =M11-N11 -> 16692 | Q11: ALLOTED WEF JUN 24. ADV 4000, RENT 2000
A12: 7 | B12: RAM P SHRESTHA | C12: G/7 | D12: 37773 | E12: 500 | F12: 2200 | G12: 4944 | H12: ='OCT 24'!G12 -> 4940 | I12: =G12-H12 -> 4 | J12: =I12*12 -> 48 | K12: 300 | L12: ='OCT 24'!O12 -> 0 | M12: =F12+J12+K12+L12 -> 2548 | N12: 2348 | O12: =M12-N12 -> 200 | Q12: ALLOTED WEF SEP 21. ADV 10000. RENT 2000
